Workbook
Name Fm: #REF!
Name JH: #REF!
Name KX: #REF!

Sheet Neutral General
A1: 2019 Recurring | H1: 2021 Recurring
A2: עד כמה אמירתו של יובל כי הוא גאה בשירותים שלו נתפסת כאותנטית בעיניך? | B2: עד כמה את/ה מאמין/ה לטענתו של יובל כי בנה את האוטובוס מתוך רצון לשמור על חופש ולא מתוך מצוקה כלכלית? | C2: האם לדעתך יובל הוא טיפוס חרוץ? | D2: האם לדעתך יובל הוא טיפוס יצירתי? | E2: עד כמה את/ה חושב/ת שיובל אוהב טבע? | F2: עד כמה מגוריו של יובל באוטובוס נתפסים בעיניך כחריגים? | G2: עד כמה את/ה חושב/ת שיובל מרוצה מסגנון חייו? | H2: עד כמה אמירתו של יובל כי הוא גאה בשירותים שלו נתפסת כאותנטית בעיניך? | I2: עד כמה את/ה מאמין/ה לטענתו של יובל כי בנה את האוטובוס מתוך רצון לשמור על חופש ולא מתוך מצוקה כלכלית? | J2: האם לדעתך יובל הוא טיפוס חרוץ? | K2: האם לדעתך יובל הוא טיפוס יצירתי? | L2: עד כמה את/ה חושב/ת שיובל אוהב טבע? | M2: עד כמה מגוריו של יובל באוטובוס נתפסים בעיניך כחריגים? | N2: עד כמה את/ה חושב/ת שיובל מרוצה מסגנון חייו?
A3: 63 | B3: 54 | C3: 72 | D3: 81 | E3: 86 | F3: 89 | G3: 87 | H3: 89 | I3: 65 | J3: 92 | K3: 96 | L3: 87 | M3: 92 | N3: 91
A4: 81 | B4: 33 | C4: 83 | D4: 100 | E4: 82 | F4: 25 | G4: 79 | H4: 98 | I4: 41 | J4: 85 | K4: 100 | L4: 86 | M4: 57 | N4: 77
A5: 71 | B5: 43 | C5: 53 | D5: 59 | E5: 76 | F5: 67 | G5: 77 | H5: 83 | I5: 56 | J5: 93 | K5: 57 | L5: 71 | M5: 76 | N5: 79
A6: 63 | B6: 35 | C6: 60 | D6: 61 | E6: 63 | F6: 67 | G6: 68 | H6: 69 | I6: 42 | J6: 71 | K6: 88 | L6: 75 | M6: 64 | N6: 87
A7: 79 | B7: 55 | C7: 78 | D7: 88 | E7: 78 | F7: 50 | G7: 67 | H7: 98 | I7: 68 | J7: 80 | K7: 79 | L7: 80 | M7: 59 | N7: 96
A8: 47 | B8: 11 | C8: 45 | D8: 76 | E8: 55 | F8: 95 | G8: 52 | H8: 45 | I8: 46 | J8: 54 | K8: 100 | L8: 67 | M8: 68 | N8: 48
A9: 83 | B9: 58 | C9: 85 | D9: 83 | E9: 64 | F9: 29 | G9: 95 | H9: 100 | I9: 81 | J9: 82 | K9: 84 | L9: 100 | M9: 42 | N9: 75
A10: 100 | B10: 80 | C10: 100 | D10: 49 | E10: 100 | F10: 49 | G10: 72 | H10: 100 | I10: 83 | J10: 100 | K10: 88 | L10: 100 | M10: 69 | N10: 65
A11: 60 | B11: 64 | C11: 17 | D11: 67 | E11: 66 | F11: 87 | G11: 42 | H11: 83 | I11: 35 | J11: 27 | K11: 85 | L11: 97 | M11: 89 | N11: 83
A12: 100 | B12: 100 | C12: 100 | D12: 100 | E12: 98 | F12: 16 | G12: 96 | H12: 100 | I12: 100 | J12: 97 | K12: 100 | L12: 100 | M12: 73 | N12: 100
A13: 0 | B13: 17 | C13: 85 | D13: 82 | E13: 62 | F13: 100 | G13: 19 | H13: 99 | I13: 29 | J13: 100 | K13: 100 | L13: 92 | M13: 97 | N13: 63
A14: 62 | B14: 88 | C14: 88 | D14: 83 | E14: 91 | F14: 78 | G14: 60 | H14: 84 | I14: 31 | J14: 83 | K14: 90 | L14: 73 | M14: 96 | N14: 60
... A23: 100 | B23: 33 | C23: 70 | D23: 91 | E23: 92 | F23: 16 | G23: 99 | H23: 94 | I23: 92 | J23: 76 | K23: 94 | L23: 88 | M23: 61 | N23: 91

Sheet Neutral  Ideology
A1: 2019 Recurring | C1: 2021 Recurring
A2: עד כמה מגוריו של יובל באוטובוס נתפסים בעיניך כחריגים? | B2: עד כמה אמירתו של יובל כי הוא גאה בשירותים שלו נתפסת כאותנטית בעיניך? | C2: עד כמה מגוריו של יובל באוטובוס נתפסים בעיניך כחריגים? | D2: עד כמה אמירתו של יובל כי הוא גאה בשירותים שלו נתפסת כאותנטית בעיניך?
A3: 89 | B3: 63 | C3: 92 | D3: 89 | F3: =AVERAGE(C3:D3) -> 90.5
A4: 25 | B4: 81 | C4: 57 | D4: 98 | F4: =AVERAGE(C4:D4) -> 77.5
A5: 67 | B5: 71 | C5: 76 | D5: 83 | F5: =AVERAGE(C5:D5) -> 79.5
A6: 67 | B6: 63 | C6: 64 | D6: 69 | F6: =AVERAGE(C6:D6) -> 66.5
A7: 50 | B7: 79 | C7: 59 | D7: 98 | F7: =AVERAGE(C7:D7) -> 78.5
A8: 95 | B8: 47 | C8: 68 | D8: 45 | F8: =AVERAGE(C8:D8) -> 56.5
A9: 29 | B9: 83 | C9: 42 | D9: 100 | F9: =AVERAGE(C9:D9) -> 71
A10: 49 | B10: 100 | C10: 69 | D10: 100 | F10: =AVERAGE(C10:D10) -> 84.5
A11: 87 | B11: 60 | C11: 89 | D11: 83 | F11: =AVERAGE(C11:D11) -> 86
A12: 16 | B12: 100 | C12: 73 | D12: 100 | F12: =AVERAGE(C12:D12) -> 86.5
A13: 100 | B13: 0 | C13: 97 | D13: 99 | F13: =AVERAGE(C13:D13) -> 98
A14: 78 | B14: 62 | C14: 96 | D14: 84 | F14: =AVERAGE(C14:D14) -> 90
... A23: 16 | B23: 100 | C23: 61 | D23: 94 | F23: =AVERAGE(C23:D23) -> 77.5

Sheet Neutral Ingroup
A1: 2019 Recurring | F1: 2019 Recurring
A2: עד כמה את/ה מאמין/ה לטענתו של יובל כי בנה את האוטובוס מתוך רצון לשמור על חופש ולא מתוך מצוקה כלכלית? | B2: האם לדעתך יובל הוא טיפוס חרוץ? | C2: האם לדעתך יובל הוא טיפוס יצירתי? | D2: עד כמה את/ה חושב/ת שיובל אוהב טבע? | E2: עד כמה את/ה חושב/ת שיובל מרוצה מסגנון חייו? | F2: עד כמה את/ה מאמין/ה לטענתו של יובל כי בנה את האוטובוס מתוך רצון לשמור על חופש ולא מתוך מצוקה כלכלית? | G2: האם לדעתך יובל הוא טיפוס חרוץ? | H2: האם לדעתך יובל הוא טיפוס יצירתי? | I2: עד כמה את/ה חושב/ת שיובל אוהב טבע? | J2: עד כמה את/ה חושב/ת שיובל מרוצה מסגנון חייו?
A3: 54 | B3: 72 | C3: 81 | D3: 86 | E3: 87 | F3: 65 | G3: 92 | H3: 96 | I3: 87 | J3: 91 | L3: =AVERAGE(F3:J3) -> 86.2
A4: 33 | B4: 83 | C4: 100 | D4: 82 | E4: 79 | F4: 41 | G4: 85 | H4: 100 | I4: 86 | J4: 77 | L4: =AVERAGE(F4:J4) -> 77.8
A5: 43 | B5: 53 | C5: 59 | D5: 76 | E5: 77 | F5: 56 | G5: 93 | H5: 57 | I5: 71 | J5: 79 | L5: =AVERAGE(F5:J5) -> 71.2
A6: 35 | B6: 60 | C6: 61 | D6: 63 | E6: 68 | F6: 42 | G6: 71 | H6: 88 | I6: 75 | J6: 87 | L6: =AVERAGE(F6:J6) -> 72.6 | M6: עד כמה את/ה מאמין/ה לטענתו של יובל כי בנה את האוטובוס מתוך רצון לשמור על חופש ולא מתוך מצוקה כלכלית?
A7: 55 | B7: 78 | C7: 88 | D7: 78 | E7: 67 | F7: 68 | G7: 80 | H7: 79 | I7: 80 | J7: 96 | L7: =AVERAGE(F7:J7) -> 80.6 | M7: האם לדעתך יובל הוא טיפוס חרוץ?
A8: 11 | B8: 45 | C8: 76 | D8: 55 | E8: 52 | F8: 46 | G8: 54 | H8: 100 | I8: 67 | J8: 48 | L8: =AVERAGE(F8:J8) -> 63 | M8: האם לדעתך יובל הוא טיפוס יצירתי?
A9: 58 | B9: 85 | C9: 83 | D9: 64 | E9: 95 | F9: 81 | G9: 82 | H9: 84 | I9: 100 | J9: 75 | L9: =AVERAGE(F9:J9) -> 84.4 | M9: עד כמה את/ה חושב/ת שיובל אוהב טבע?
A10: 80 | B10: 100 | C10: 49 | D10: 100 | E10: 72 | F10: 83 | G10: 100 | H10: 88 | I10: 100 | J10: 65 | L10: =AVERAGE(F10:J10) -> 87.2 | M10: עד כמה את/ה חושב/ת שיובל מרוצה מסגנון חייו?
A11: 64 | B11: 17 | C11: 67 | D11: 66 | E11: 42 | F11: 35 | G11: 27 | H11: 85 | I11: 97 | J11: 83 | L11: =AVERAGE(F11:J11) -> 65.4
A12: 100 | B12: 100 | C12: 100 | D12: 98 | E12: 96 | F12: 100 | G12: 97 | H12: 100 | I12: 100 | J12: 100 | L12: =AVERAGE(F12:J12) -> 99.4
A13: 17 | B13: 85 | C13: 82 | D13: 62 | E13: 19 | F13: 29 | G13: 100 | H13: 100 | I13: 92 | J13: 63 | L13: =AVERAGE(F13:J13) -> 76.8
A14: 88 | B14: 88 | C14: 83 | D14: 91 | E14: 60 | F14: 31 | G14: 83 | H14: 90 | I14: 73 | J14: 60 | L14: =AVERAGE(F14:J14) -> 67.4
A15: 57 | B15: 55 | C15: 54 | D15: 62 | E15: 57 | F15: 68 | G15: 100 | H15: 97 | I15: 82 | J15: 24 | L15: =AVERAGE(F15:J15) -> 74.2
A16: 68 | B16: 93 | C16: 88 | D16: 89 | E16: 79 | F16: 74 | G16: 87 | H16: 84 | I16: 92 | J16: 86 | L16: =AVERAGE(F16:J16) -> 84.6
A17: 82 | B17: 62 | C17: 100 | D17: 86 | E17: 73 | F17: 81 | G17: 73 | H17: 53 | I17: 54 | J17: 61 | L17: =AVERAGE(F17:J17) -> 64.4
A18: 72 | B18: 81 | C18: 85 | D18: 49 | E18: 77 | F18: 58 | G18: 74 | H18: 83 | I18: 66 | J18: 92 | L18: =AVERAGE(F18:J18) -> 74.6
A19: 100 | B19: 51 | C19: 76 | D19: 91 | E19: 61 | F19: 42 | G19: 81 | H19: 85 | I19: 79 | J19: 53 | L19: =AVERAGE(F19:J19) -> 68
A20: 79 | B20: 100 | C20: 100 | D20: 100 | E20: 86 | F20: 50 | G20: 100 | H20: 100 | I20: 77 | J20: 50 | L20: =AVERAGE(F20:J20) -> 75.4
A21: 88 | B21: 84 | C21: 94 | D21: 99 | E21: 93 | F21: 69 | G21: 91 | H21: 79 | I21: 95 | J21: 85 | L21: =AVERAGE(F21:J21) -> 83.8
A22: 21 | B22: 100 | C22: 100 | D22: 77 | E22: 81 | F22: 72 | G22: 100 | H22: 100 | I22: 69 | J22: 76 | L22: =AVERAGE(F22:J22) -> 83.4
A23: 33 | B23: 70 | C23: 91 | D23: 92 | E23: 99 | F23: 92 | G23: 76 | H23: 94 | I23: 88 | J23: 91 | L23: =AVERAGE(F23:J23) -> 88.2

Sheet Yamin Hadash General
A1: 2019 Recurring | D1: 2021 Recurring | G1: 2021 Only Once
A2: עד כמה את/ה מסכים/ה עם הטענה כי רק ייצוג מירבי של מפלגת הימין החדש יבטיח קואליציה שתשמור על מדיניות ימנית? | B2: עד כמה הדמויות הבאות נתפסות בעיניך כאמינות? 0 = דמות לא אמינה בכלל, 100 = דמות מאוד אמינה - נפתלי בנט | C2: עד כמה הדמויות הבאות נתפסות בעיניך כאמינות? 0 = דמות לא אמינה בכלל, 100 = דמות מאוד אמינה - איילת שקד | D2: עד כמה את/ה מסכים/ה עם הטענה כי רק ייצוג מירבי של מפלגת הימין החדש יבטיח קואליציה שתשמור על מדיניות ימנית? | E2: עד כמה הדמויות הבאות נתפסות בעיניך כאמינות? 0 = דמות לא אמינה בכלל, 100 = דמות מאוד אמינה - נפתלי בנט | F2: עד כמה הדמויות הבאות נתפסות בעיניך כאמינות? 0 = דמות לא אמינה בכלל, 100 = דמות מאוד אמינה - איילת שקד | G2: עד כמה דעתך על איילת שקד השתנתה מאז הצפייה בנאמר עליה בסרטון זה במרץ 2019? | H2: עד כמה הדעה שלך לגבי הסרטון בו בנט ושקד מתנגדים לנתניהו וחלוקת ירושלים השתנתה מאז צפית בו לראשונה במרץ 2019? | I2: עד כמה הדעה שלך כלפי נפתלי בנט השתנתה מאז מרץ 2019? | J2: עד כמה הדעה שלך כלפי איילת שקד השתנתה מאז מרץ 2019?
A3: 50 | B3: 39 | C3: 39 | D3: 60 | E3: 75 | F3: 75 | G3: 58 | H3: 2 | I3: 81 | J3: 1
A4: 0 | B4: 70 | C4: 60 | D4: 35 | E4: 90 | F4: 65 | G4: 16 | H4: 27 | I4: 95 | J4: 5
A5: 74 | B5: 65 | C5: 80 | D5: 46 | E5: 60 | F5: 50 | G5: 58 | H5: 0 | I5: 68 | J5: 40
A6: 65 | B6: 51 | C6: 50 | D6: 78 | E6: 10 | F6: 5 | G6: 24 | H6: 32 | I6: 55 | J6: 40
A7: 48 | B7: 0 | C7: 0 | D7: 60 | E7: 77 | F7: 7 | G7: 45 | H7: 60 | I7: 89 | J7: 50
A8: 0 | B8: 0 | C8: 5 | D8: 93 | E8: 49 | F8: 84 | G8: 65 | H8: 49 | I8: 94 | J8: 90
A9: 18 | B9: 5 | C9: 8 | D9: 0 | E9: 37 | F9: 20 | G9: 20 | H9: 11 | I9: 76 | J9: 65
A10: 100 | B10: 0 | C10: 0 | D10: 81 | E10: 100 | F10: 54 | G10: 83 | H10: 0 | I10: 100 | J10: 0
A11: 78 | B11: 50 | C11: 64 | D11: 36 | E11: 70 | F11: 32 | G11: 24 | H11: 33 | I11: 87 | J11: 2
A12: 31 | B12: 50 | C12: 100 | D12: 76 | E12: 50 | F12: 50 | G12: 8 | H12: 46 | I12: 58 | J12: 27
A13: 69 | B13: 90 | C13: 100 | D13: 0 | E13: 0 | F13: 15 | G13: 95 | H13: 100 | I13: 100 | J13: 94
A14: 66 | B14: 54 | C14: 55 | D14: 80 | E14: 69 | F14: 12 | G14: 89 | H14: 18 | I14: 83 | J14: 94
... A23: 87 | B23: 30 | C23: 30 | D23: 87 | E23: 65 | F23: 50 | G23: 13 | H23: 0 | I23: 26 | J23: 1
F26: t-values | G26: =(AVERAGE(G3:G23)/(STDEV(G3:G23)/SQRT(COUNT(G3:G23)))) -> 6.5900684 | H26: =(AVERAGE(H3:H23)/(STDEV(H3:H23)/SQRT(COUNT(H3:H23)))) -> 5.3206679 | I26: =(AVERAGE(I3:I23)/(STDEV(I3:I23)/SQRT(COUNT(I3:I23)))) -> 17.272977 | J26: =(AVERAGE(J3:J23)/(STDEV(J3:J23)/SQRT(COUNT(J3:J23)))) -> 5.8026719
F27: p-values | G27: =TDIST(G26, (COUNT(G3:G23) - 1), 2) -> 2.0275803e-06 | H27: =TDIST(H26, (COUNT(H3:H23) - 1), 2) -> 3.3034747e-05 | I27: =TDIST(I26, (COUNT(I3:I23) - 1), 2) -> 1.7375872e-13 | J27: =TDIST(J26, (COUNT(J3:J23) - 1), 2) -> 1.119596e-05
F29: average | G29: =AVERAGE(G3:G23) -> 47.095238 | H29: =AVERAGE(H3:H23) -> 38.142857 | I29: =AVERAGE(I3:I23) -> 78.809524 | J29: =AVERAGE(J3:J23) -> 46.714286

Sheet Yamin Hadash Ideology
A1: 2019 Recurring | B1: 2021 Recurring | C1: 2021 Only Once
A2: עד כמה את/ה מסכים/ה עם הטענה כי רק ייצוג מירבי של מפלגת הימין החדש יבטיח קואליציה שתשמור על מדיניות ימנית? | B2: עד כמה את/ה מסכים/ה עם הטענה כי רק ייצוג מירבי של מפלגת הימין החדש יבטיח קואליציה שתשמור על מדיניות ימנית? | C2: עד כמה הדעה שלך לגבי הסרטון בו בנט ושקד מתנגדים לנתניהו וחלוקת ירושלים השתנתה מאז צפית בו לראשונה במרץ 2019?
A3: 50 | B3: 60 | C3: 2 | E3: =AVERAGE(B3:C3) -> 31
A4: 0 | B4: 35 | C4: 27 | E4: =AVERAGE(B4:C4) -> 31
A5: 74 | B5: 46 | C5: 0 | E5: =AVERAGE(B5:C5) -> 23
A6: 65 | B6: 78 | C6: 32 | E6: =AVERAGE(B6:C6) -> 55
A7: 48 | B7: 60 | C7: 60 | E7: =AVERAGE(B7:C7) -> 60
A8: 0 | B8: 93 | C8: 49 | E8: =AVERAGE(B8:C8) -> 71
A9: 18 | B9: 0 | C9: 11 | E9: =AVERAGE(B9:C9) -> 5.5
A10: 100 | B10: 81 | C10: 0 | E10: =AVERAGE(B10:C10) -> 40.5
A11: 78 | B11: 36 | C11: 33 | E11: =AVERAGE(B11:C11) -> 34.5
A12: 31 | B12: 76 | C12: 46 | E12: =AVERAGE(B12:C12) -> 61
A13: 69 | B13: 0 | C13: 100 | E13: =AVERAGE(B13:C13) -> 50
A14: 66 | B14: 80 | C14: 18 | E14: =AVERAGE(B14:C14) -> 49
... A23: 87 | B23: 87 | C23: 0 | E23: =AVERAGE(B23:C23) -> 43.5
B26: t-values | C26: =(AVERAGE(C3:C23)/(STDEV(C3:C23)/SQRT(COUNT(C3:C23)))) -> 5.3206679
B27: p-values | C27: =TDIST(C26, (COUNT(C3:C23) - 1), 2) -> 3.3034747e-05

Sheet Yamin Hadash Ingroup
A1: 2019 Recurring | C1: 2019 Recurring | E1: 2021 Only Once
A2: עד כמה הדמויות הבאות נתפסות בעיניך כאמינות? 0 = דמות לא אמינה בכלל, 100 = דמות מאוד אמינה - נפתלי בנט | B2: עד כמה הדמויות הבאות נתפסות בעיניך כאמינות? 0 = דמות לא אמינה בכלל, 100 = דמות מאוד אמינה - איילת שקד | C2: עד כמה הדמויות הבאות נתפסות בעיניך כאמינות? 0 = דמות לא אמינה בכלל, 100 = דמות מאוד אמינה - נפתלי בנט | D2: עד כמה הדמויות הבאות נתפסות בעיניך כאמינות? 0 = דמות לא אמינה בכלל, 100 = דמות מאוד אמינה - איילת שקד | E2: עד כמה דעתך על איילת שקד השתנתה מאז הצפייה בנאמר עליה בסרטון זה במרץ 2019? | F2: עד כמה הדעה שלך כלפי נפתלי בנט השתנתה מאז מרץ 2019? | G2: עד כמה הדעה שלך כלפי איילת שקד השתנתה מאז מרץ 2019?
A3: 39 | B3: 39 | C3: 75 | D3: 75 | E3: 58 | F3: 81 | G3: 1 | I3: =AVERAGE(C3:G3) -> 58
A4: 70 | B4: 60 | C4: 90 | D4: 65 | E4: 16 | F4: 95 | G4: 5 | I4: =AVERAGE(C4:G4) -> 54.2
A5: 65 | B5: 80 | C5: 60 | D5: 50 | E5: 58 | F5: 68 | G5: 40 | I5: =AVERAGE(C5:G5) -> 55.2
A6: 51 | B6: 50 | C6: 10 | D6: 5 | E6: 24 | F6: 55 | G6: 40 | I6: =AVERAGE(C6:G6) -> 26.8
A7: 0 | B7: 0 | C7: 77 | D7: 7 | E7: 45 | F7: 89 | G7: 50 | I7: =AVERAGE(C7:G7) -> 53.6
A8: 0 | B8: 5 | C8: 49 | D8: 84 | E8: 65 | F8: 94 | G8: 90 | I8: =AVERAGE(C8:G8) -> 76.4
A9: 5 | B9: 8 | C9: 37 | D9: 20 | E9: 20 | F9: 76 | G9: 65 | I9: =AVERAGE(C9:G9) -> 43.6
A10: 0 | B10: 0 | C10: 100 | D10: 54 | E10: 83 | F10: 100 | G10: 0 | I10: =AVERAGE(C10:G10) -> 67.4
A11: 50 | B11: 64 | C11: 70 | D11: 32 | E11: 24 | F11: 87 | G11: 2 | I11: =AVERAGE(C11:G11) -> 43
A12: 50 | B12: 100 | C12: 50 | D12: 50 | E12: 8 | F12: 58 | G12: 27 | I12: =AVERAGE(C12:G12) -> 38.6
A13: 90 | B13: 100 | C13: 0 | D13: 15 | E13: 95 | F13: 100 | G13: 94 | I13: =AVERAGE(C13:G13) -> 60.8
A14: 54 | B14: 55 | C14: 69 | D14: 12 | E14: 89 | F14: 83 | G14: 94 | I14: =AVERAGE(C14:G14) -> 69.4
... A23: 30 | B23: 30 | C23: 65 | D23: 50 | E23: 13 | F23: 26 | G23: 1 | I23: =AVERAGE(C23:G23) -> 31
D26: t-values | E26: =(AVERAGE(E3:E23)/(STDEV(E3:E23)/SQRT(COUNT(E3:E23)))) -> 6.5900684 | F26: =(AVERAGE(F3:F23)/(STDEV(F3:F23)/SQRT(COUNT(F3:F23)))) -> 17.272977 | G26: =(AVERAGE(G3:G23)/(STDEV(G3:G23)/SQRT(COUNT(G3:G23)))) -> 5.8026719
D27: p-values | E27: =TDIST(E26, (COUNT(E3:E23) - 1), 2) -> 2.0275803e-06 | F27: =TDIST(F26, (COUNT(F3:F23) - 1), 2) -> 1.7375872e-13 | G27: =TDIST(G26, (COUNT(G3:G23) - 1), 2) -> 1.119596e-05

Sheet Gantz-Lapid General
A1: 2019 Recurring | X1: 2021 Recurring | AU1: 2021 Only Once
A2: עד כמה את/ה חושב/ת שלפיד מאמין שגנץ יהיה ראש ממשלה מצוין? | B2: עד כמה בני גנץ מעורר בך כל אחת מהתחושות הבאות?0 = כלל לא, 100 = מאוד - גאווה | C2: עד כמה בני גנץ מעורר בך כל אחת מהתחושות הבאות?0 = כלל לא, 100 = מאוד - תקווה | D2: עד כמה בני גנץ מעורר בך כל אחת מהתחושות הבאות?0 = כלל לא, 100 = מאוד - אהבה | E2: עד כמה בני גנץ מעורר בך כל אחת מהתחושות הבאות?0 = כלל לא, 100 = מאוד - כעס | F2: עד כמה בני גנץ מעורר בך כל אחת מהתחושות הבאות?0 = כלל לא, 100 = מאוד - בוז | G2: עד כמה בני גנץ מעורר בך כל אחת מהתחושות הבאות?0 = כלל לא, 100 = מאוד - שנאה | H2: עד כמה בני גנץ מעורר בך כל אחת מהתחושות הבאות?0 = כלל לא, 100 = מאוד - חרדה | I2: עד כמה בני גנץ מעורר בך כל אחת מהתחושות הבאות?0 = כלל לא, 100 = מאוד - ייאוש | J2: עד כמה בני גנץ מעורר בך כל אחת מהתחושות הבאות?0 = כלל לא, 100 = מאוד - אדישות | K2: עד כמה בני גנץ מעורר בך כל אחת מהתחושות הבאות?0 = כלל לא, 100 = מאוד - גועל | L2: עד כמה יאיר לפיד מעורר בך כל אחת מהתחושות הבאות?0 = כלל לא, 100 = מאוד - גאווה | M2: עד כמה יאיר לפיד מעורר בך כל אחת מהתחושות הבאות?0 = כלל לא, 100 = מאוד - תקווה | N2: עד כמה יאיר לפיד מעורר בך כל אחת מהתחושות הבאות?0 = כלל לא, 100 = מאוד - אהבה | O2: עד כמה יאיר לפיד מעורר בך כל אחת מהתחושות הבאות?0 = כלל לא, 100 = מאוד - כעס | P2: עד כמה יאיר לפיד מעורר בך כל אחת מהתחושות הבאות?0 = כלל לא, 100 = מאוד - בוז | Q2: עד כמה יאיר לפיד מעורר בך כל אחת מהתחושות הבאות?0 = כלל לא, 100 = מאוד - שנאה | R2: עד כמה יאיר לפיד מעורר בך כל אחת מהתחושות הבאות?0 = כלל לא, 100 = מאוד - חרדה | S2: עד כמה יאיר לפיד מעורר בך כל אחת מהתחושות הבאות?0 = כלל לא, 100 = מאוד - ייאוש | T2: עד כמה יאיר לפיד מעורר בך כל אחת מהתחושות הבאות?0 = כלל לא, 100 = מאוד - אדישות | U2: עד כמה יאיר לפיד מעורר בך כל אחת מהתחושות הבאות?0 = כלל לא, 100 = מאוד - גועל | V2: עד כמה הדמויות הבאות נתפסות בעיניך כאמינות? 0 = דמות לא אמינה בכלל, 100 = דמות מאוד אמינה - בני גנץ | W2: עד כמה הדמויות הבאות נתפסות בעיניך כאמינות? 0 = דמות לא אמינה בכלל, 100 = דמות מאוד אמינה - יאיר לפיד | X2: עד כמה את/ה חושב/ת שלפיד מאמין שגנץ יהיה ראש ממשלה מצוין? | Y2: עד כמה הדמויות הבאות נתפסות בעיניך כאמינות? 0 = דמות לא אמינה בכלל, 100 = דמות מאוד אמינה - בני גנץ | Z2: עד כמה הדמויות הבאות נתפסות בעיניך כאמינות? 0 = דמות לא אמינה בכלל, 100 = דמות מאוד אמינה - יאיר לפיד | AA2: עד כמה בני גנץ מעורר בך כל אחת מהתחושות הבאות?0 = כלל לא, 100 = מאוד - גאווה | AB2: עד כמה בני גנץ מעורר בך כל אחת מהתחושות הבאות?0 = כלל לא, 100 = מאוד - תקווה | AC2: עד כמה בני גנץ מעורר בך כל אחת מהתחושות הבאות?0 = כלל לא, 100 = מאוד - אהבה | AD2: עד כמה בני גנץ מעורר בך כל אחת מהתחושות הבאות?0 = כלל לא, 100 = מאוד - כעס | AE2: עד כמה בני גנץ מעורר בך כל אחת מהתחושות הבאות?0 = כלל לא, 100 = מאוד - בוז | AF2: עד כמה בני גנץ מעורר בך כל אחת מהתחושות הבאות?0 = כלל לא, 100 = מאוד - שנאה | AG2: עד כמה בני גנץ מעורר בך כל אחת מהתחושות הבאות?0 = כלל לא, 100 = מאוד - חרדה | AH2: עד כמה בני גנץ מעורר בך כל אחת מהתחושות הבאות?0 = כלל לא, 100 = מאוד - ייאוש | AI2: עד כמה בני גנץ מעורר בך כל אחת מהתחושות הבאות?0 = כלל לא, 100 = מאוד - אדישות | AJ2: עד כמה בני גנץ מעורר בך כל אחת מהתחושות הבאות?0 = כלל לא, 100 = מאוד - גועל | AK2: עד כמה יאיר לפיד מעורר בך כל אחת מהתחושות הבאות?0 = כלל לא, 100 = מאוד - גאווה | AL2: עד כמה יאיר לפיד מעורר בך כל אחת מהתחושות הבאות?0 = כלל לא, 100 = מאוד - תקווה | AM2: עד כמה יאיר לפיד מעורר בך כל אחת מהתחושות הבאות?0 = כלל לא, 100 = מאוד - אהבה | AN2: עד כמה יאיר לפיד מעורר בך כל אחת מהתחושות הבאות?0 = כלל לא, 100 = מאוד - כעס | AO2: עד כמה יאיר לפיד מעורר בך כל אחת מהתחושות הבאות?0 = כלל לא, 100 = מאוד - בוז | AP2: עד כמה יאיר לפיד מעורר בך כל אחת מהתחושות הבאות?0 = כלל לא, 100 = מאוד - שנאה | AQ2: עד כמה יאיר לפיד מעורר בך כל אחת מהתחושות הבאות?0 = כלל לא, 100 = מאוד - חרדה | AR2: עד כמה יאיר לפיד מעורר בך כל אחת מהתחושות הבאות?0 = כלל לא, 100 = מאוד - ייאוש | AS2: עד כמה יאיר לפיד מעורר בך כל אחת מהתחושות הבאות?0 = כלל לא, 100 = מאוד - אדישות | AT2: עד כמה יאיר לפיד מעורר בך כל אחת מהתחושות הבאות?0 = כלל לא, 100 = מאוד - גועל | AU2: עד כמה דעתך על הקטע בו מסופר 'מה ביבי חושב על גנץ' השתנתה מאז מרץ 2019? | AV2: עד כמה דעתך על ריאיון העבר של נתניהו, בו הוא מדבר על הבעייתיות בכהונת ראש ממשלה תחת כתבי אישום, השתנתה מאז מרץ 2019? | AW2: עד כמה דעתך כלפי הסרטון השתנתה מאז צפית בו לראשונה במרץ 2019? | AX2: עד כמה דעתך כלפי נאומו של גנץ השתנתה מאז מרץ 2019? | AY2: עד כמה דעתך כלפי נאומו של לפיד השתנתה מאז מרץ 2019? | AZ2: עד כמה דעתך כלפי לפיד השתנתה מאז מרץ 2019?
A3: 51 | B3: 10 | C3: 60 | D3: 10 | E3: 0 | F3: 30 | G3: 0 | H3: 0 | I3: 0 | J3: 50 | K3: 0 | L3: 60 | M3: 70 | N3: 0 | O3: 0 | P3: 20 | Q3: 0 | R3: 0 | S3: 0 | T3: 0 | U3: 0 | V3: 39 | W3: 61 | X3: 63 | Y3: 99 | Z3: 67 | AA3: 30 | AB3: 40 | AC3: 0 | AD3: 30 | AE3: 0 | AF3: 0 | AG3: 0 | AH3: 0 | AI3: 20 | AJ3: 0 | AK3: 35 | AL3: 40 | AM3: 0 | AN3: 20 | AO3: 20 | AP3: 0 | AQ3: 0 | AR3: 0 | AS3: 0 | AT3: 11 | AU3: 1 | AV3: 1 | AW3: 1 | AX3: 87 | AY3: 1 | AZ3: 70
A4: 44 | B4: 20 | C4: 70 | D4: 40 | E4: 0 | F4: 0 | G4: 0 | H4: 0 | I4: 0 | J4: 100 | K4: 0 | L4: 35 | M4: 70 | N4: 85 | O4: 0 | P4: 0 | Q4: 0 | R4: 0 | S4: 30 | T4: 55 | U4: 0 | V4: 30 | W4: 40 | X4: 60 | Y4: 85 | Z4: 70 | AA4: 30 | AB4: 30 | AC4: 60 | AD4: 0 | AE4: 0 | AF4: 0 | AG4: 0 | AH4: 0 | AI4: 50 | AJ4: 0 | AK4: 70 | AL4: 70 | AM4: 80 | AN4: 0 | AO4: 0 | AP4: 0 | AQ4: 0 | AR4: 0 | AS4: 0 | AT4: 0 | AU4: 97 | AV4: 3 | AW4: 77 | AX4: 14 | AY4: 16 | AZ4: 27
A5: 33 | B5: 0 | C5: 0 | D5: 0 | E5: 0 | F5: 60 | G5: 26 | H5: 0 | I5: 42 | J5: 90 | K5: 11 | L5: 0 | M5: 0 | N5: 0 | O5: 40 | P5: 80 | Q5: 60 | R5: 0 | S5: 40 | T5: 40 | U5: 60 | V5: 25 | W5: 20 | X5: 26 | Y5: 5 | Z5: 90 | AA5: 1 | AB5: 1 | AC5: 1 | AD5: 49 | AE5: 100 | AF5: 90 | AG5: 2 | AH5: 70 | AI5: 46 | AJ5: 12 | AK5: 60 | AL5: 60 | AM5: 60 | AN5: 2 | AO5: 40 | AP5: 5 | AQ5: 2 | AR5: 2 | AS5: 43 | AT5: 13 | AU5: 0 | AV5: 0 | AW5: 0 | AX5: 13 | AY5: 100 | AZ5: 100
A6: 65 | B6: 61 | C6: 71 | D6: 40 | E6: 16 | F6: 3 | G6: 2 | H6: 4 | I6: 11 | J6: 23 | K6: 3 | L6: 50 | M6: 70 | N6: 46 | O6: 17 | P6: 16 | Q6: 3 | R6: 20 | S6: 17 | T6: 29 | U6: 1 | V6: 90 | W6: 61 | X6: 35 | Y6: 40 | Z6: 50 | AA6: 12 | AB6: 38 | AC6: 38 | AD6: 4 | AE6: 7 | AF6: 3 | AG6: 31 | AH6: 5 | AI6: 38 | AJ6: 3 | AK6: 48 | AL6: 57 | AM6: 38 | AN6: 9 | AO6: 10 | AP6: 5 | AQ6: 8 | AR6: 13 | AS6: 32 | AT6: 7 | AU6: 33 | AV6: 20 | AW6: 16 | AX6: 34 | AY6: 65 | AZ6: 71
A7: 86 | B7: 19 | C7: 92 | D7: 34 | E7: 0 | F7: 0 | G7: 0 | H7: 0 | I7: 0 | J7: 0 | K7: 0 | L7: 0 | M7: 9 | N7: 0 | O7: 0 | P7: 0 | Q7: 0 | R7: 0 | S7: 0 | T7: 0 | U7: 0 | V7: 81 | W7: 64 | X7: 55 | Y7: 4 | Z7: 79 | AA7: 0 | AB7: 0 | AC7: 0 | AD7: 0 | AE7: 0 | AF7: 0 | AG7: 0 | AH7: 0 | AI7: 48 | AJ7: 0 | AK7: 57 | AL7: 56 | AM7: 9 | AN7: 0 | AO7: 0 | AP7: 0 | AQ7: 0 | AR7: 0 | AS7: 0 | AT7: 0 | AU7: 43 | AV7: 17 | AW7: 15 | AX7: 73 | AY7: 71 | AZ7: 74
A8: 58 | B8: 55 | C8: 80 | D8: 0 | E8: 0 | F8: 0 | G8: 0 | H8: 0 | I8: 0 | J8: 0 | K8: 0 | L8: 23 | M8: 75 | N8: 7 | O8: 0 | P8: 0 | Q8: 0 | R8: 0 | S8: 67 | T8: 0 | U8: 0 | V8: 59 | W8: 40 | X8: 25 | Y8: 90 | Z8: 49 | AA8: 65 | AB8: 42 | AC8: 29 | AD8: 12 | AE8: 0 | AF8: 0 | AG8: 0 | AH8: 0 | AI8: 9 | AJ8: 0 | AK8: 18 | AL8: 29 | AM8: 3 | AN8: 0 | AO8: 29 | AP8: 0 | AQ8: 0 | AR8: 8 | AS8: 0 | AT8: 0 | AU8: 69 | AV8: 0 | AW8: 26 | AX8: 68 | AY8: 38 | AZ8: 85
A9: 79 | B9: 20 | C9: 25 | D9: 5 | E9: 0 | F9: 3 | G9: 0 | H9: 8 | I9: 5 | J9: 15 | K9: 0 | L9: 5 | M9: 12 | N9: 0 | O9: 0 | P9: 5 | Q9: 0 | R9: 8 | S9: 3 | T9: 15 | U9: 3 | V9: 50 | W9: 30 | X9: 32 | Y9: 39 | Z9: 41 | AA9: 19 | AB9: 18 | AC9: 6 | AD9: 2 | AE9: 3 | AF9: 0 | AG9: 0 | AH9: 63 | AI9: 44 | AJ9: 5 | AK9: 64 | AL9: 60 | AM9: 25 | AN9: 4 | AO9: 14 | AP9: 2 | AQ9: 7 | AR9: 31 | AS9: 21 | AT9: 0 | AU9: 65 | AV9: 23 | AW9: 21 | AX9: 75 | AY9: 67 | AZ9: 81
A10: 76 | B10: 0 | C10: 100 | D10: 56 | E10: 0 | F10: 0 | G10: 0 | H10: 0 | I10: 0 | J10: 0 | K10: 0 | L10: 0 | M10: 0 | N10: 0 | O10: 0 | P10: 53 | Q10: 100 | R10: 0 | S10: 0 | T10: 100 | U10: 0 | V10: 82 | W10: 0 | X10: 0 | Y10: 52 | Z10: 53 | AA10: 0 | AB10: 0 | AC10: 0 | AD10: 100 | AE10: 100 | AF10: 100 | AG10: 51 | AH10: 100 | AI10: 100 | AJ10: 0 | AK10: 65 | AL10: 56 | AM10: 26 | AN10: 0 | AO10: 0 | AP10: 0 | AQ10: 0 | AR10: 0 | AS10: 0 | AT10: 0 | AU10: 0 | AV10: 0 | AW10: 0 | AX10: 0 | AY10: 35 | AZ10: 56
A11: 58 | B11: 18 | C11: 53 | D11: 32 | E11: 0 | F11: 0 | G11: 0 | H11: 0 | I11: 22 | J11: 54 | K11: 0 | L11: 13 | M11: 21 | N11: 0 | O11: 0 | P11: 41 | Q11: 0 | R11: 0 | S11: 48 | T11: 28 | U11: 29 | V11: 81 | W11: 38 | X11: 90 | Y11: 80 | Z11: 90 | AA11: 20 | AB11: 10 | AC11: 31 | AD11: 59 | AE11: 33 | AF11: 0 | AG11: 0 | AH11: 39 | AI11: 32 | AJ11: 0 | AK11: 71 | AL11: 90 | AM11: 14 | AN11: 0 | AO11: 40 | AP11: 0 | AQ11: 0 | AR11: 0 | AS11: 33 | AT11: 0 | AU11: 82 | AV11: 80 | AW11: 0 | AX11: 56 | AY11: 98 | AZ11: 95
A12: 93 | B12: 80 | C12: 50 | D12: 80 | E12: 40 | F12: 0 | G12: 0 | H12: 10 | I12: 60 | J12: 0 | K12: 0 | L12: 30 | M12: 50 | N12: 30 | O12: 50 | P12: 30 | Q12: 0 | R12: 20 | S12: 50 | T12: 30 | U12: 10 | V12: 100 | W12: 70 | X12: 14 | Y12: 5 | Z12: 90 | AA12: 0 | AB12: 5 | AC12: 10 | AD12: 70 | AE12: 90 | AF12: 51 | AG12: 50 | AH12: 100 | AI12: 30 | AJ12: 20 | AK12: 60 | AL12: 60 | AM12: 60 | AN12: 12 | AO12: 11 | AP12: 0 | AQ12: 0 | AR12: 0 | AS12: 0 | AT12: 10 | AU12: 78 | AV12: 0 | AW12: 28 | AX12: 100 | AY12: 80 | AZ12: 67
A13: 85 | B13: 30 | C13: 0 | D13: 0 | E13: 0 | F13: 50 | G13: 0 | H13: 30 | I13: 0 | J13: 0 | K13: 0 | L13: 0 | M13: 0 | N13: 0 | O13: 40 | P13: 60 | Q13: 0 | R13: 0 | S13: 0 | T13: 30 | U13: 10 | V13: 70 | W13: 18 | X13: 14 | Y13: 40 | Z13: 0 | AA13: 10 | AB13: 0 | AC13: 0 | AD13: 0 | AE13: 50 | AF13: 0 | AG13: 20 | AH13: 0 | AI13: 70 | AJ13: 0 | AK13: 0 | AL13: 0 | AM13: 0 | AN13: 30 | AO13: 40 | AP13: 0 | AQ13: 0 | AR13: 0 | AS13: 50 | AT13: 0 | AU13: 0 | AV13: 0 | AW13: 3 | AX13: 14 | AY13: 10 | AZ13: 12
A14: 18 | B14: 14 | C14: 14 | D14: 16 | E14: 16 | F14: 52 | G14: 15 | H14: 57 | I14: 19 | J14: 71 | K14: 8 | L14: 28 | M14: 20 | N14: 9 | O14: 69 | P14: 18 | Q14: 13 | R14: 62 | S14: 34 | T14: 27 | U14: 5 | V14: 52 | W14: 64 | X14: 29 | Y14: 50 | Z14: 67 | AA14: 7 | AB14: 3 | AC14: 4 | AD14: 71 | AE14: 18 | AF14: 41 | AG14: 60 | AH14: 60 | AI14: 2 | AJ14: 1 | AK14: 50 | AL14: 39 | AM14: 34 | AN14: 10 | AO14: 5 | AP14: 4 | AQ14: 25 | AR14: 60 | AS14: 2 | AT14: 2 | AU14: 19 | AV14: 10 | AW14: 5 | AX14: 33 | AY14: 65 | AZ14: 77
... A23: 91 | B23: 0 | C23: 30 | D23: 0 | E23: 0 | F23: 12 | G23: 0 | H23: 0 | I23: 0 | J23: 0 | K23: 0 | L23: 0 | M23: 31 | N23: 5 | O23: 0 | P23: 0 | Q23: 0 | R23: 0 | S23: 0 | T23: 0 | U23: 0 | V23: 70 | W23: 70 | X23: 91 | Y23: 65 | Z23: 90 | AA23: 0 | AB23: 0 | AC23: 0 | AD23: 0 | AE23: 20 | AF23: 0 | AG23: 0 | AH23: 20 | AI23: 50 | AJ23: 5 | AK23: 70 | AL23: 31 | AM23: 31 | AN23: 0 | AO23: 10 | AP23: 0 | AQ23: 0 | AR23: 0 | AS23: 5 | AT23: 0 | AU23: 0 | AV23: 0 | AW23: 0 | AX23: 100 | AY23: 75 | AZ23: 85
AT26: t-values | AU26: =(AVERAGE(AU3:AU23)/(STDEV(AU3:AU23)/SQRT(COUNT(AU3:AU23)))) -> 4.6915048 | AV26: =(AVERAGE(AV3:AV23)/(STDEV(AV3:AV23)/SQRT(COUNT(AV3:AV23)))) -> 3.4993877 | AW26: =(AVERAGE(AW3:AW23)/(STDEV(AW3:AW23)/SQRT(COUNT(AW3:AW23)))) -> 4.1090406 | AX26: =(AVERAGE(AX3:AX23)/(STDEV(AX3:AX23)/SQRT(COUNT(AX3:AX23)))) -> 7.0665643 | AY26: =(AVERAGE(AY3:AY23)/(STDEV(AY3:AY23)/SQRT(COUNT(AY3:AY23)))) -> 7.8303627 | AZ26: =(AVERAGE(AZ3:AZ23)/(STDEV(AZ3:AZ23)/SQRT(COUNT(AZ3:AZ23)))) -> 10.43023
AT27: p-values | AU27: =TDIST(AU26, (COUNT(AU3:AU23) - 1), 2) -> 0.00014015633 | AV27: =TDIST(AV26, (COUNT(AV3:AV23) - 1), 2) -> 0.0022583224 | AW27: =TDIST(AW26, (COUNT(AW3:AW23) - 1), 2) -> 0.0005451747 | AX27: =TDIST(AX26, (COUNT(AX3:AX23) - 1), 2) -> 7.4956416e-07 | AY27: =TDIST(AY26, (COUNT(AY3:AY23) - 1), 2) -> 1.6206167e-07 | AZ27: =TDIST(AZ26, (COUNT(AZ3:AZ23) - 1), 2) -> 1.5508532e-09
A35: עד כמה את/ה חושב/ת שלפיד מאמין שגנץ יהיה ראש ממשלה מצוין? | B35: עד כמה בני גנץ מעורר בך כל אחת מהתחושות הבאות?0 = כלל לא, 100 = מאוד - גאווה | C35: עד כמה בני גנץ מעורר בך כל אחת מהתחושות הבאות?0 = כלל לא, 100 = מאוד - תקווה | D35: עד כמה בני גנץ מעורר בך כל אחת מהתחושות הבאות?0 = כלל לא, 100 = מאוד - אהבה | E35: עד כמה בני גנץ מעורר בך כל אחת מהתחושות הבאות?0 = כלל לא, 100 = מאוד - כעס | F35: עד כמה בני גנץ מעורר בך כל אחת מהתחושות הבאות?0 = כלל לא, 100 = מאוד - בוז | G35: עד כמה בני גנץ מעורר בך כל אחת מהתחושות הבאות?0 = כלל לא, 100 = מאוד - שנאה | H35: עד כמה בני גנץ מעורר בך כל אחת מהתחושות הבאות?0 = כלל לא, 100 = מאוד - חרדה | I35: עד כמה בני גנץ מעורר בך כל אחת מהתחושות הבאות?0 = כלל לא, 100 = מאוד - ייאוש | J35: עד כמה בני גנץ מעורר בך כל אחת מהתחושות הבאות?0 = כלל לא, 100 = מאוד - אדישות | K35: עד כמה בני גנץ מעורר בך כל אחת מהתחושות הבאות?0 = כלל לא, 100 = מאוד - גועל | L35: עד כמה יאיר לפיד מעורר בך כל אחת מהתחושות הבאות?0 = כלל לא, 100 = מאוד - גאווה | M35: עד כמה יאיר לפיד מעורר בך כל אחת מהתחושות הבאות?0 = כלל לא, 100 = מאוד - תקווה | N35: עד כמה יאיר לפיד מעורר בך כל אחת מהתחושות הבאות?0 = כלל לא, 100 = מאוד - אהבה | O35: עד כמה יאיר לפיד מעורר בך כל אחת מהתחושות הבאות?0 = כלל לא, 100 = מאוד - כעס | P35: עד כמה יאיר לפיד מעורר בך כל אחת מהתחושות הבאות?0 = כלל לא, 100 = מאוד - בוז | Q35: עד כמה יאיר לפיד מעורר בך כל אחת מהתחושות הבאות?0 = כלל לא, 100 = מאוד - שנאה | R35: עד כמה יאיר לפיד מעורר בך כל אחת מהתחושות הבאות?0 = כלל לא, 100 = מאוד - חרדה | S35: עד כמה יאיר לפיד מעורר בך כל אחת מהתחושות הבאות?0 = כלל לא, 100 = מאוד - ייאוש | T35: עד כמה יאיר לפיד מעורר בך כל אחת מהתחושות הבאות?0 = כלל לא, 100 = מאוד - אדישות | U35: עד כמה יאיר לפיד מעורר בך כל אחת מהתחושות הבאות?0 = כלל לא, 100 = מאוד - גועל | V35: עד כמה הדמויות הבאות נתפסות בעיניך כאמינות? 0 = דמות לא אמינה בכלל, 100 = דמות מאוד אמינה - בני גנץ | W35: עד כמה הדמויות הבאות נתפסות בעיניך כאמינות? 0 = דמות לא אמינה בכלל, 100 = דמות מאוד אמינה - יאיר לפיד
A37: עד כמה את/ה חושב/ת שלפיד מאמין שגנץ יהיה ראש ממשלה מצוין? | B37: עד כמה הדמויות הבאות נתפסות בעיניך כאמינות? 0 = דמות לא אמינה בכלל, 100 = דמות מאוד אמינה - בני גנץ | C37: עד כמה הדמויות הבאות נתפסות בעיניך כאמינות? 0 = דמות לא אמינה בכלל, 100 = דמות מאוד אמינה - יאיר לפיד | D37: עד כמה בני גנץ מעורר בך כל אחת מהתחושות הבאות?0 = כלל לא, 100 = מאוד - גאווה | E37: עד כמה בני גנץ מעורר בך כל אחת מהתחושות הבאות?0 = כלל לא, 100 = מאוד - תקווה | F37: עד כמה בני גנץ מעורר בך כל אחת מהתחושות הבאות?0 = כלל לא, 100 = מאוד - אהבה | G37: עד כמה בני גנץ מעורר בך כל אחת מהתחושות הבאות?0 = כלל לא, 100 = מאוד - כעס | H37: עד כמה בני גנץ מעורר בך כל אחת מהתחושות הבאות?0 = כלל לא, 100 = מאוד - בוז | I37: עד כמה בני גנץ מעורר בך כל אחת מהתחושות הבאות?0 = כלל לא, 100 = מאוד - שנאה | J37: עד כמה בני גנץ מעורר בך כל אחת מהתחושות הבאות?0 = כלל לא, 100 = מאוד - חרדה | K37: עד כמה בני גנץ מעורר בך כל אחת מהתחושות הבאות?0 = כלל לא, 100 = מאוד - ייאוש | L37: עד כמה בני גנץ מעורר בך כל אחת מהתחושות הבאות?0 = כלל לא, 100 = מאוד - אדישות | M37: עד כמה בני גנץ מעורר בך כל אחת מהתחושות הבאות?0 = כלל לא, 100 = מאוד - גועל | N37: עד כמה יאיר לפיד מעורר בך כל אחת מהתחושות הבאות?0 = כלל לא, 100 = מאוד - גאווה | O37: עד כמה יאיר לפיד מעורר בך כל אחת מהתחושות הבאות?0 = כלל לא, 100 = מאוד - תקווה | P37: עד כמה יאיר לפיד מעורר בך כל אחת מהתחושות הבאות?0 = כלל לא, 100 = מאוד - אהבה | Q37: עד כמה יאיר לפיד מעורר בך כל אחת מהתחושות הבאות?0 = כלל לא, 100 = מאוד - כעס | R37: עד כמה יאיר לפיד מעורר בך כל אחת מהתחושות הבאות?0 = כלל לא, 100 = מאוד - בוז | S37: עד כמה יאיר לפיד מעורר בך כל אחת מהתחושות הבאות?0 = כלל לא, 100 = מאוד - שנאה | T37: עד כמה יאיר לפיד מעורר בך כל אחת מהתחושות הבאות?0 = כלל לא, 100 = מאוד - חרדה | U37: עד כמה יאיר לפיד מעורר בך כל אחת מהתחושות הבאות?0 = כלל לא, 100 = מאוד - ייאוש | V37: עד כמה יאיר לפיד מעורר בך כל אחת מהתחושות הבאות?0 = כלל לא, 100 = מאוד - אדישות | W37: עד כמה יאיר לפיד מעורר בך כל אחת מהתחושות הבאות?0 = כלל לא, 100 = מאוד - גועל

Sheet Gantz-Lapid Ideology
A1: 2021 Only Once
A2: עד כמה דעתך על ריאיון העבר של נתניהו, בו הוא מדבר על הבעייתיות בכהונת ראש ממשלה תחת כתבי אישום, השתנתה מאז מרץ 2019? | B2: עד כמה דעתך כלפי הסרטון השתנתה מאז צפית בו לראשונה במרץ 2019? | C2: עד כמה דעתך כלפי נאומו של לפיד השתנתה מאז מרץ 2019? | D2: עד כמה דעתך כלפי נאומו של גנץ השתנתה מאז מרץ 2019?
A3: 1 | B3: 1 | C3: 1 | D3: 87 | F3: =AVERAGE(A3:D3) -> 22.5
A4: 3 | B4: 77 | C4: 16 | D4: 14 | F4: =AVERAGE(A4:D4) -> 27.5
A5: 0 | B5: 0 | C5: 100 | D5: 13 | F5: =AVERAGE(A5:D5) -> 28.25
A6: 20 | B6: 16 | C6: 65 | D6: 34 | F6: =AVERAGE(A6:D6) -> 33.75
A7: 17 | B7: 15 | C7: 71 | D7: 73 | F7: =AVERAGE(A7:D7) -> 44
A8: 0 | B8: 26 | C8: 38 | D8: 68 | F8: =AVERAGE(A8:D8) -> 33
A9: 23 | B9: 21 | C9: 67 | D9: 75 | F9: =AVERAGE(A9:D9) -> 46.5
A10: 0 | B10: 0 | C10: 35 | D10: 0 | F10: =AVERAGE(A10:D10) -> 8.75
A11: 80 | B11: 0 | C11: 98 | D11: 56 | F11: =AVERAGE(A11:D11) -> 58.5
A12: 0 | B12: 28 | C12: 80 | D12: 100 | F12: =AVERAGE(A12:D12) -> 52
A13: 0 | B13: 3 | C13: 10 | D13: 14 | F13: =AVERAGE(A13:D13) -> 6.75
A14: 10 | B14: 5 | C14: 65 | D14: 33 | F14: =AVERAGE(A14:D14) -> 28.25
... A23: 0 | B23: 0 | C23: 75 | D23: 100 | F23: =AVERAGE(A23:D23) -> 43.75
A26: =(AVERAGE(A3:A23)/(STDEV(A3:A23)/SQRT(COUNT(A3:A23)))) -> 3.4993877 | B26: =(AVERAGE(B3:B23)/(STDEV(B3:B23)/SQRT(COUNT(B3:B23)))) -> 4.1090406 | C26: =(AVERAGE(C3:C23)/(STDEV(C3:C23)/SQRT(COUNT(C3:C23)))) -> 7.8303627 | D26: =(AVERAGE(D3:D23)/(STDEV(D3:D23)/SQRT(COUNT(D3:D23)))) -> 7.0665643 | F26: t-values
A27: =TDIST(A26, (COUNT(A3:A23) - 1), 2) -> 0.0022583224 | B27: =TDIST(B26, (COUNT(B3:B23) - 1), 2) -> 0.0005451747 | C27: =TDIST(C26, (COUNT(C3:C23) - 1), 2) -> 1.6206167e-07 | D27: =TDIST(D26, (COUNT(D3:D23) - 1), 2) -> 7.4956416e-07 | F27: p-values

Sheet Gantz-Lapid Ingroup
A1: 2019 Recurring | X1: 2019 Recurring | AU1: 2021 Only Once
A2: עד כמה את/ה חושב/ת שלפיד מאמין שגנץ יהיה ראש ממשלה מצוין? | B2: עד כמה בני גנץ מעורר בך כל אחת מהתחושות הבאות?0 = כלל לא, 100 = מאוד - גאווה | C2: עד כמה בני גנץ מעורר בך כל אחת מהתחושות הבאות?0 = כלל לא, 100 = מאוד - תקווה | D2: עד כמה בני גנץ מעורר בך כל אחת מהתחושות הבאות?0 = כלל לא, 100 = מאוד - אהבה | E2: עד כמה בני גנץ מעורר בך כל אחת מהתחושות הבאות?0 = כלל לא, 100 = מאוד - כעס | F2: עד כמה בני גנץ מעורר בך כל אחת מהתחושות הבאות?0 = כלל לא, 100 = מאוד - בוז | G2: עד כמה בני גנץ מעורר בך כל אחת מהתחושות הבאות?0 = כלל לא, 100 = מאוד - שנאה | H2: עד כמה בני גנץ מעורר בך כל אחת מהתחושות הבאות?0 = כלל לא, 100 = מאוד - חרדה | I2: עד כמה בני גנץ מעורר בך כל אחת מהתחושות הבאות?0 = כלל לא, 100 = מאוד - ייאוש | J2: עד כמה בני גנץ מעורר בך כל אחת מהתחושות הבאות?0 = כלל לא, 100 = מאוד - אדישות | K2: עד כמה בני גנץ מעורר בך כל אחת מהתחושות הבאות?0 = כלל לא, 100 = מאוד - גועל | L2: עד כמה יאיר לפיד מעורר בך כל אחת מהתחושות הבאות?0 = כלל לא, 100 = מאוד - גאווה | M2: עד כמה יאיר לפיד מעורר בך כל אחת מהתחושות הבאות?0 = כלל לא, 100 = מאוד - תקווה | N2: עד כמה יאיר לפיד מעורר בך כל אחת מהתחושות הבאות?0 = כלל לא, 100 = מאוד - אהבה | O2: עד כמה יאיר לפיד מעורר בך כל אחת מהתחושות הבאות?0 = כלל לא, 100 = מאוד - כעס | P2: עד כמה יאיר לפיד מעורר בך כל אחת מהתחושות הבאות?0 = כלל לא, 100 = מאוד - בוז | Q2: עד כמה יאיר לפיד מעורר בך כל אחת מהתחושות הבאות?0 = כלל לא, 100 = מאוד - שנאה | R2: עד כמה יאיר לפיד מעורר בך כל אחת מהתחושות הבאות?0 = כלל לא, 100 = מאוד - חרדה | S2: עד כמה יאיר לפיד מעורר בך כל אחת מהתחושות הבאות?0 = כלל לא, 100 = מאוד - ייאוש | T2: עד כמה יאיר לפיד מעורר בך כל אחת מהתחושות הבאות?0 = כלל לא, 100 = מאוד - אדישות | U2: עד כמה יאיר לפיד מעורר בך כל אחת מהתחושות הבאות?0 = כלל לא, 100 = מאוד - גועל | V2: עד כמה הדמויות הבאות נתפסות בעיניך כאמינות? 0 = דמות לא אמינה בכלל, 100 = דמות מאוד אמינה - בני גנץ | W2: עד כמה הדמויות הבאות נתפסות בעיניך כאמינות? 0 = דמות לא אמינה בכלל, 100 = דמות מאוד אמינה - יאיר לפיד | X2: עד כמה את/ה חושב/ת שלפיד מאמין שגנץ יהיה ראש ממשלה מצוין? | Y2: עד כמה הדמויות הבאות נתפסות בעיניך כאמינות? 0 = דמות לא אמינה בכלל, 100 = דמות מאוד אמינה - בני גנץ | Z2: עד כמה הדמויות הבאות נתפסות בעיניך כאמינות? 0 = דמות לא אמינה בכלל, 100 = דמות מאוד אמינה - יאיר לפיד | AA2: עד כמה בני גנץ מעורר בך כל אחת מהתחושות הבאות?0 = כלל לא, 100 = מאוד - גאווה | AB2: עד כמה בני גנץ מעורר בך כל אחת מהתחושות הבאות?0 = כלל לא, 100 = מאוד - תקווה | AC2: עד כמה בני גנץ מעורר בך כל אחת מהתחושות הבאות?0 = כלל לא, 100 = מאוד - אהבה | AD2: עד כמה בני גנץ מעורר בך כל אחת מהתחושות הבאות?0 = כלל לא, 100 = מאוד - כעס | AE2: עד כמה בני גנץ מעורר בך כל אחת מהתחושות הבאות?0 = כלל לא, 100 = מאוד - בוז | AF2: עד כמה בני גנץ מעורר בך כל אחת מהתחושות הבאות?0 = כלל לא, 100 = מאוד - שנאה | AG2: עד כמה בני גנץ מעורר בך כל אחת מהתחושות הבאות?0 = כלל לא, 100 = מאוד - חרדה | AH2: עד כמה בני גנץ מעורר בך כל אחת מהתחושות הבאות?0 = כלל לא, 100 = מאוד - ייאוש | AI2: עד כמה בני גנץ מעורר בך כל אחת מהתחושות הבאות?0 = כלל לא, 100 = מאוד - אדישות | AJ2: עד כמה בני גנץ מעורר בך כל אחת מהתחושות הבאות?0 = כלל לא, 100 = מאוד - גועל | AK2: עד כמה יאיר לפיד מעורר בך כל אחת מהתחושות הבאות?0 = כלל לא, 100 = מאוד - גאווה | AL2: עד כמה יאיר לפיד מעורר בך כל אחת מהתחושות הבאות?0 = כלל לא, 100 = מאוד - תקווה | AM2: עד כמה יאיר לפיד מעורר בך כל אחת מהתחושות הבאות?0 = כלל לא, 100 = מאוד - אהבה | AN2: עד כמה יאיר לפיד מעורר בך כל אחת מהתחושות הבאות?0 = כלל לא, 100 = מאוד - כעס | AO2: עד כמה יאיר לפיד מעורר בך כל אחת מהתחושות הבאות?0 = כלל לא, 100 = מאוד - בוז | AP2: עד כמה יאיר לפיד מעורר בך כל אחת מהתחושות הבאות?0 = כלל לא, 100 = מאוד - שנאה | AQ2: עד כמה יאיר לפיד מעורר בך כל אחת מהתחושות הבאות?0 = כלל לא, 100 = מאוד - חרדה | AR2: עד כמה יאיר לפיד מעורר בך כל אחת מהתחושות הבאות?0 = כלל לא, 100 = מאוד - ייאוש | AS2: עד כמה יאיר לפיד מעורר בך כל אחת מהתחושות הבאות?0 = כלל לא, 100 = מאוד - אדישות | AT2: עד כמה יאיר לפיד מעורר בך כל אחת מהתחושות הבאות?0 = כלל לא, 100 = מאוד - גועל | AU2: עד כמה דעתך על הקטע בו מסופר 'מה ביבי חושב על גנץ' השתנתה מאז מרץ 2019? | AV2: עד כמה דעתך כלפי לפיד השתנתה מאז מרץ 2019? | BA2: average_gantz_differences_abed
A3: 51 | B3: 10 | C3: 60 | D3: 10 | E3: 0 | F3: 30 | G3: 0 | H3: 0 | I3: 0 | J3: 50 | K3: 0 | L3: 60 | M3: 70 | N3: 0 | O3: 0 | P3: 20 | Q3: 0 | R3: 0 | S3: 0 | T3: 0 | U3: 0 | V3: 39 | W3: 61 | X3: 63 | Y3: 99 | Z3: 67 | AA3: 30 | AB3: 40 | AC3: 0 | AD3: 30 | AE3: 0 | AF3: 0 | AG3: 0 | AH3: 0 | AI3: 20 | AJ3: 0 | AK3: 35 | AL3: 40 | AM3: 0 | AN3: 20 | AO3: 20 | AP3: 0 | AQ3: 0 | AR3: 0 | AS3: 0 | AT3: 11 | AU3: 1 | AV3: 70 | AX3: =AVERAGE(X3:AV3) -> 21.84 | BA3: 33.545455
A4: 44 | B4: 20 | C4: 70 | D4: 40 | E4: 0 | F4: 0 | G4: 0 | H4: 0 | I4: 0 | J4: 100 | K4: 0 | L4: 35 | M4: 70 | N4: 85 | O4: 0 | P4: 0 | Q4: 0 | R4: 0 | S4: 30 | T4: 55 | U4: 0 | V4: 30 | W4: 40 | X4: 60 | Y4: 85 | Z4: 70 | AA4: 30 | AB4: 30 | AC4: 60 | AD4: 0 | AE4: 0 | AF4: 0 | AG4: 0 | AH4: 0 | AI4: 50 | AJ4: 0 | AK4: 70 | AL4: 70 | AM4: 80 | AN4: 0 | AO4: 0 | AP4: 0 | AQ4: 0 | AR4: 0 | AS4: 0 | AT4: 0 | AU4: 97 | AV4: 27 | AX4: =AVERAGE(X4:AV4) -> 29.16 | BA4: 31.818182
A5: 33 | B5: 0 | C5: 0 | D5: 0 | E5: 0 | F5: 60 | G5: 26 | H5: 0 | I5: 42 | J5: 90 | K5: 11 | L5: 0 | M5: 0 | N5: 0 | O5: 40 | P5: 80 | Q5: 60 | R5: 0 | S5: 40 | T5: 40 | U5: 60 | V5: 25 | W5: 20 | X5: 26 | Y5: 5 | Z5: 90 | AA5: 1 | AB5: 1 | AC5: 1 | AD5: 49 | AE5: 100 | AF5: 90 | AG5: 2 | AH5: 70 | AI5: 46 | AJ5: 12 | AK5: 60 | AL5: 60 | AM5: 60 | AN5: 2 | AO5: 40 | AP5: 5 | AQ5: 2 | AR5: 2 | AS5: 43 | AT5: 13 | AU5: 0 | AV5: 100 | AX5: =AVERAGE(X5:AV5) -> 35.2 | BA5: 40.181818
A6: 65 | B6: 61 | C6: 71 | D6: 40 | E6: 16 | F6: 3 | G6: 2 | H6: 4 | I6: 11 | J6: 23 | K6: 3 | L6: 50 | M6: 70 | N6: 46 | O6: 17 | P6: 16 | Q6: 3 | R6: 20 | S6: 17 | T6: 29 | U6: 1 | V6: 90 | W6: 61 | X6: 35 | Y6: 40 | Z6: 50 | AA6: 12 | AB6: 38 | AC6: 38 | AD6: 4 | AE6: 7 | AF6: 3 | AG6: 31 | AH6: 5 | AI6: 38 | AJ6: 3 | AK6: 48 | AL6: 57 | AM6: 38 | AN6: 9 | AO6: 10 | AP6: 5 | AQ6: 8 | AR6: 13 | AS6: 32 | AT6: 7 | AU6: 33 | AV6: 71 | AX6: =AVERAGE(X6:AV6) -> 25.4 | BA6: 18.909091
A7: 86 | B7: 19 | C7: 92 | D7: 34 | E7: 0 | F7: 0 | G7: 0 | H7: 0 | I7: 0 | J7: 0 | K7: 0 | L7: 0 | M7: 9 | N7: 0 | O7: 0 | P7: 0 | Q7: 0 | R7: 0 | S7: 0 | T7: 0 | U7: 0 | V7: 81 | W7: 64 | X7: 55 | Y7: 4 | Z7: 79 | AA7: 0 | AB7: 0 | AC7: 0 | AD7: 0 | AE7: 0 | AF7: 0 | AG7: 0 | AH7: 0 | AI7: 48 | AJ7: 0 | AK7: 57 | AL7: 56 | AM7: 9 | AN7: 0 | AO7: 0 | AP7: 0 | AQ7: 0 | AR7: 0 | AS7: 0 | AT7: 0 | AU7: 43 | AV7: 74 | AX7: =AVERAGE(X7:AV7) -> 17 | BA7: 9.6363636
A8: 58 | B8: 55 | C8: 80 | D8: 0 | E8: 0 | F8: 0 | G8: 0 | H8: 0 | I8: 0 | J8: 0 | K8: 0 | L8: 23 | M8: 75 | N8: 7 | O8: 0 | P8: 0 | Q8: 0 | R8: 0 | S8: 67 | T8: 0 | U8: 0 | V8: 59 | W8: 40 | X8: 25 | Y8: 90 | Z8: 49 | AA8: 65 | AB8: 42 | AC8: 29 | AD8: 12 | AE8: 0 | AF8: 0 | AG8: 0 | AH8: 0 | AI8: 9 | AJ8: 0 | AK8: 18 | AL8: 29 | AM8: 3 | AN8: 0 | AO8: 29 | AP8: 0 | AQ8: 0 | AR8: 8 | AS8: 0 | AT8: 0 | AU8: 69 | AV8: 85 | AX8: =AVERAGE(X8:AV8) -> 22.48 | BA8: 24.727273
A9: 79 | B9: 20 | C9: 25 | D9: 5 | E9: 0 | F9: 3 | G9: 0 | H9: 8 | I9: 5 | J9: 15 | K9: 0 | L9: 5 | M9: 12 | N9: 0 | O9: 0 | P9: 5 | Q9: 0 | R9: 8 | S9: 3 | T9: 15 | U9: 3 | V9: 50 | W9: 30 | X9: 32 | Y9: 39 | Z9: 41 | AA9: 19 | AB9: 18 | AC9: 6 | AD9: 2 | AE9: 3 | AF9: 0 | AG9: 0 | AH9: 63 | AI9: 44 | AJ9: 5 | AK9: 64 | AL9: 60 | AM9: 25 | AN9: 4 | AO9: 14 | AP9: 2 | AQ9: 7 | AR9: 31 | AS9: 21 | AT9: 0 | AU9: 65 | AV9: 81 | AX9: =AVERAGE(X9:AV9) -> 25.84 | BA9: 17.272727
A10: 76 | B10: 0 | C10: 100 | D10: 56 | E10: 0 | F10: 0 | G10: 0 | H10: 0 | I10: 0 | J10: 0 | K10: 0 | L10: 0 | M10: 0 | N10: 0 | O10: 0 | P10: 53 | Q10: 100 | R10: 0 | S10: 0 | T10: 100 | U10: 0 | V10: 82 | W10: 0 | X10: 0 | Y10: 52 | Z10: 53 | AA10: 0 | AB10: 0 | AC10: 0 | AD10: 100 | AE10: 100 | AF10: 100 | AG10: 51 | AH10: 100 | AI10: 100 | AJ10: 0 | AK10: 65 | AL10: 56 | AM10: 26 | AN10: 0 | AO10: 0 | AP10: 0 | AQ10: 0 | AR10: 0 | AS10: 0 | AT10: 0 | AU10: 0 | AV10: 56 | AX10: =AVERAGE(X10:AV10) -> 34.36 | BA10: 59.909091
A11: 58 | B11: 18 | C11: 53 | D11: 32 | E11: 0 | F11: 0 | G11: 0 | H11: 0 | I11: 22 | J11: 54 | K11: 0 | L11: 13 | M11: 21 | N11: 0 | O11: 0 | P11: 41 | Q11: 0 | R11: 0 | S11: 48 | T11: 28 | U11: 29 | V11: 81 | W11: 38 | X11: 90 | Y11: 80 | Z11: 90 | AA11: 20 | AB11: 10 | AC11: 31 | AD11: 59 | AE11: 33 | AF11: 0 | AG11: 0 | AH11: 39 | AI11: 32 | AJ11: 0 | AK11: 71 | AL11: 90 | AM11: 14 | AN11: 0 | AO11: 40 | AP11: 0 | AQ11: 0 | AR11: 0 | AS11: 33 | AT11: 0 | AU11: 82 | AV11: 95 | AX11: =AVERAGE(X11:AV11) -> 36.36 | BA11: 32.909091
A12: 93 | B12: 80 | C12: 50 | D12: 80 | E12: 40 | F12: 0 | G12: 0 | H12: 10 | I12: 60 | J12: 0 | K12: 0 | L12: 30 | M12: 50 | N12: 30 | O12: 50 | P12: 30 | Q12: 0 | R12: 20 | S12: 50 | T12: 30 | U12: 10 | V12: 100 | W12: 70 | X12: 14 | Y12: 5 | Z12: 90 | AA12: 0 | AB12: 5 | AC12: 10 | AD12: 70 | AE12: 90 | AF12: 51 | AG12: 50 | AH12: 100 | AI12: 30 | AJ12: 20 | AK12: 60 | AL12: 60 | AM12: 60 | AN12: 12 | AO12: 11 | AP12: 0 | AQ12: 0 | AR12: 0 | AS12: 0 | AT12: 10 | AU12: 78 | AV12: 67 | AX12: =AVERAGE(X12:AV12) -> 35.72 | BA12: 49
A13: 85 | B13: 30 | C13: 0 | D13: 0 | E13: 0 | F13: 50 | G13: 0 | H13: 30 | I13: 0 | J13: 0 | K13: 0 | L13: 0 | M13: 0 | N13: 0 | O13: 40 | P13: 60 | Q13: 0 | R13: 0 | S13: 0 | T13: 30 | U13: 10 | V13: 70 | W13: 18 | X13: 14 | Y13: 40 | Z13: 0 | AA13: 10 | AB13: 0 | AC13: 0 | AD13: 0 | AE13: 50 | AF13: 0 | AG13: 20 | AH13: 0 | AI13: 70 | AJ13: 0 | AK13: 0 | AL13: 0 | AM13: 0 | AN13: 30 | AO13: 40 | AP13: 0 | AQ13: 0 | AR13: 0 | AS13: 50 | AT13: 0 | AU13: 0 | AV13: 12 | AX13: =AVERAGE(X13:AV13) -> 13.44 | BA13: 16.363636
A14: 18 | B14: 14 | C14: 14 | D14: 16 | E14: 16 | F14: 52 | G14: 15 | H14: 57 | I14: 19 | J14: 71 | K14: 8 | L14: 28 | M14: 20 | N14: 9 | O14: 69 | P14: 18 | Q14: 13 | R14: 62 | S14: 34 | T14: 27 | U14: 5 | V14: 52 | W14: 64 | X14: 29 | Y14: 50 | Z14: 67 | AA14: 7 | AB14: 3 | AC14: 4 | AD14: 71 | AE14: 18 | AF14: 41 | AG14: 60 | AH14: 60 | AI14: 2 | AJ14: 1 | AK14: 50 | AL14: 39 | AM14: 34 | AN14: 10 | AO14: 5 | AP14: 4 | AQ14: 25 | AR14: 60 | AS14: 2 | AT14: 2 | AU14: 19 | AV14: 77 | AX14: =AVERAGE(X14:AV14) -> 29.6 | BA14: 30.090909
... A23: 91 | B23: 0 | C23: 30 | D23: 0 | E23: 0 | F23: 12 | G23: 0 | H23: 0 | I23: 0 | J23: 0 | K23: 0 | L23: 0 | M23: 31 | N23: 5 | O23: 0 | P23: 0 | Q23: 0 | R23: 0 | S23: 0 | T23: 0 | U23: 0 | V23: 70 | W23: 70 | X23: 91 | Y23: 65 | Z23: 90 | AA23: 0 | AB23: 0 | AC23: 0 | AD23: 0 | AE23: 20 | AF23: 0 | AG23: 0 | AH23: 20 | AI23: 50 | AJ23: 5 | AK23: 70 | AL23: 31 | AM23: 31 | AN23: 0 | AO23: 10 | AP23: 0 | AQ23: 0 | AR23: 0 | AS23: 5 | AT23: 0 | AU23: 0 | AV23: 85 | AX23: =AVERAGE(X23:AV23) -> 22.92 | BA23: 17.545455
AT26: t-values | AU26: =(AVERAGE(AU3:AU23)/(STDEV(AU3:AU23)/SQRT(COUNT(AU3:AU23)))) -> 4.6915048 | AV26: =(AVERAGE(AV3:AV23)/(STDEV(AV3:AV23)/SQRT(COUNT(AV3:AV23)))) -> 10.43023
AT27: p-values | AU27: =TDIST(AU26, (COUNT(AU3:AU23) - 1), 2) -> 0.00014015633 | AV27: =TDIST(AV26, (COUNT(AV3:AV23) - 1), 2) -> 1.5508532e-09 | BA27: =B3-Y3 -> -89 | BB27: =C3-Z3 -> -7 | BC27: =D3-AA3 -> -20 | BD27: =E3-AB3 -> -40 | BE27: =F3-AC3 -> 30 | BF27: =G3-AD3 -> -30 | BG27: =H3-AE3 -> 0 | BH27: =I3-AF3 -> 0 | ... BJ27: =K3-AH3 -> 0 | BK27: =(V3-Y3) -> -60 | BM27: =ABS(AVERAGE(BA27:BK27)) -> 15.090909
BA28: =B4-Y4 -> -65 | BB28: =C4-Z4 -> 0 | BC28: =D4-AA4 -> 10 | BD28: =E4-AB4 -> -30 | BE28: =F4-AC4 -> -60 | BF28: =G4-AD4 -> 0 | BG28: =H4-AE4 -> 0 | BH28: =I4-AF4 -> 0 | ... BJ28: =K4-AH4 -> 0 | BK28: =(V4-Y4) -> -55 | BM28: =ABS(AVERAGE(BA28:BK28)) -> 9.0909091
BA29: =B5-Y5 -> -5 | BB29: =C5-Z5 -> -90 | BC29: =D5-AA5 -> -1 | BD29: =E5-AB5 -> -1 | BE29: =F5-AC5 -> 59 | BF29: =G5-AD5 -> -23 | BG29: =H5-AE5 -> -100 | BH29: =I5-AF5 -> -48 | ... BJ29: =K5-AH5 -> -59 | BK29: =(V5-Y5) -> 20 | BM29: =ABS(AVERAGE(BA29:BK29)) -> 14.545455
BA30: =B6-Y6 -> 21 | BB30: =C6-Z6 -> 21 | BC30: =D6-AA6 -> 28 | BD30: =E6-AB6 -> -22 | BE30: =F6-AC6 -> -35 | BF30: =G6-AD6 -> -2 | BG30: =H6-AE6 -> -3 | BH30: =I6-AF6 -> 8 | ... BJ30: =K6-AH6 -> -2 | BK30: =(V6-Y6) -> 50 | BM30: =ABS(AVERAGE(BA30:BK30)) -> 5.0909091
BA31: =B7-Y7 -> 15 | BB31: =C7-Z7 -> 13 | BC31: =D7-AA7 -> 34 | BD31: =E7-AB7 -> 0 | BE31: =F7-AC7 -> 0 | BF31: =G7-AD7 -> 0 | BG31: =H7-AE7 -> 0 | BH31: =I7-AF7 -> 0 | ... BJ31: =K7-AH7 -> 0 | BK31: =(V7-Y7) -> 77 | BM31: =ABS(AVERAGE(BA31:BK31)) -> 12.636364
BA32: =B8-Y8 -> -35 | BB32: =C8-Z8 -> 31 | BC32: =D8-AA8 -> -65 | BD32: =E8-AB8 -> -42 | BE32: =F8-AC8 -> -29 | BF32: =G8-AD8 -> -12 | BG32: =H8-AE8 -> 0 | BH32: =I8-AF8 -> 0 | ... BJ32: =K8-AH8 -> 0 | BK32: =(V8-Y8) -> -31 | BM32: =ABS(AVERAGE(BA32:BK32)) -> 16.636364
BA33: =B9-Y9 -> -19 | BB33: =C9-Z9 -> -16 | BC33: =D9-AA9 -> -14 | BD33: =E9-AB9 -> -18 | BE33: =F9-AC9 -> -3 | BF33: =G9-AD9 -> -2 | BG33: =H9-AE9 -> 5 | BH33: =I9-AF9 -> 5 | ... BJ33: =K9-AH9 -> -63 | BK33: =(V9-Y9) -> 11 | BM33: =ABS(AVERAGE(BA33:BK33)) -> 9
BA34: =B10-Y10 -> -52 | BB34: =C10-Z10 -> 47 | BC34: =D10-AA10 -> 56 | BD34: =E10-AB10 -> 0 | BE34: =F10-AC10 -> 0 | BF34: =G10-AD10 -> -100 | BG34: =H10-AE10 -> -100 | BH34: =I10-AF10 -> -100 | ... BJ34: =K10-AH10 -> -100 | BK34: =(V10-Y10) -> 30 | BM34: =ABS(AVERAGE(BA34:BK34)) -> 33.636364
BA35: =B11-Y11 -> -62 | BB35: =C11-Z11 -> -37 | BC35: =D11-AA11 -> 12 | BD35: =E11-AB11 -> -10 | BE35: =F11-AC11 -> -31 | BF35: =G11-AD11 -> -59 | BG35: =H11-AE11 -> -33 | BH35: =I11-AF11 -> 22 | ... BJ35: =K11-AH11 -> -39 | BK35: =(V11-Y11) -> 1 | BM35: =ABS(AVERAGE(BA35:BK35)) -> 16.545455
BA36: =B12-Y12 -> 75 | BB36: =C12-Z12 -> -40 | BC36: =D12-AA12 -> 80 | BD36: =E12-AB12 -> 35 | BE36: =F12-AC12 -> -10 | BF36: =G12-AD12 -> -70 | BG36: =H12-AE12 -> -80 | BH36: =I12-AF12 -> 9 | ... BJ36: =K12-AH12 -> -100 | BK36: =(V12-Y12) -> 95 | BM36: =ABS(AVERAGE(BA36:BK36)) -> 5.0909091
BA37: =B13-Y13 -> -10 | BB37: =C13-Z13 -> 0 | BC37: =D13-AA13 -> -10 | BD37: =E13-AB13 -> 0 | BE37: =F13-AC13 -> 50 | BF37: =G13-AD13 -> 0 | BG37: =H13-AE13 -> -20 | BH37: =I13-AF13 -> 0 | ... BJ37: =K13-AH13 -> 0 | BK37: =(V13-Y13) -> 30 | BM37: =ABS(AVERAGE(BA37:BK37)) -> 1.8181818
BA38: =B14-Y14 -> -36 | BB38: =C14-Z14 -> -53 | BC38: =D14-AA14 -> 9 | BD38: =E14-AB14 -> 13 | BE38: =F14-AC14 -> 48 | BF38: =G14-AD14 -> -56 | BG38: =H14-AE14 -> 39 | BH38: =I14-AF14 -> -22 | ... BJ38: =K14-AH14 -> -52 | BK38: =(V14-Y14) -> 2 | BM38: =ABS(AVERAGE(BA38:BK38)) -> 8.8181818
BA39: =B15-Y15 -> -1 | BB39: =C15-Z15 -> -1 | BC39: =D15-AA15 -> 0 | BD39: =E15-AB15 -> 0 | BE39: =F15-AC15 -> 100 | BF39: =G15-AD15 -> -1 | BG39: =H15-AE15 -> -100 | BH39: =I15-AF15 -> 100 | ... BJ39: =K15-AH15 -> -75 | BK39: =(V15-Y15) -> 5 | BM39: =ABS(AVERAGE(BA39:BK39)) -> 2.4545455
... BA47: =B23-Y23 -> -65 | BB47: =C23-Z23 -> -60 | BC47: =D23-AA23 -> 0 | BD47: =E23-AB23 -> 0 | BE47: =F23-AC23 -> 12 | BF47: =G23-AD23 -> 0 | BG47: =H23-AE23 -> -20 | BH47: =I23-AF23 -> 0 | ... BJ47: =K23-AH23 -> -20 | BK47: =(V23-Y23) -> 5 | BM47: =ABS(AVERAGE(BA47:BK47)) -> 13.454545

Sheet Likud General
A1: 2019 Recurring | F1: 2021 Recurring | K1: 2021 Only Once
A2: עד כמה לדעתך ביבי האחראי היחיד והישיר להצלחות האדירות של ישראל בעשור האחרון? | B2: עד כמה את/ה חושב/ת שהאמירה "המצב הביטחוני, הכלכלי והחברתי בישראל מעולם לא היו טובים יותר" נכונה? | C2: עד כמה לדעתך החקירות וכתב האישום מהווים רדיפה פוליטית של השמאל והתקשרות השמאלנית בישראל? | D2: עד כמה לדעתך החקירות וכתב האישום מהווים חלק מעבודתה הלגיטימית של התקשורת ככלב השמירה של הדמוקרטיה ושל השמאל כאופוזיציה? | E2: עד כמה את/ה מאמין/ה שבתום ההליכים המשפטיים תוכח חפותו המוחלטת של ביבי? | F2: עד כמה לדעתך ביבי האחראי היחיד והישיר להצלחות האדירות של ישראל בעשור האחרון? | G2: עד כמה את/ה חושב/ת שהאמירה "המצב הביטחוני, הכלכלי והחברתי בישראל מעולם לא היו טובים יותר" נכונה? | H2: עד כמה לדעתך החקירות וכתב האישום מהווים רדיפה פוליטית של השמאל והתקשרות השמאלנית בישראל? | I2: עד כמה לדעתך החקירות וכתב האישום מהווים חלק מעבודתה הלגיטימית של התקשורת ככלב השמירה של הדמוקרטיה ושל השמאל כאופוזיציה? | J2: עד כמה את/ה מאמין/ה שבתום ההליכים המשפטיים תוכח חפותו המוחלטת של ביבי? | K2: עד כמה דעתך על החלק בסרטון בו נתניהו מדבר על כך שמצבה של ישראל מעולם לא היה טוב יותר, השתנתה מאז מרץ 2019? | L2: האם דעתך על הקמת ממשלה עם המפלגות הערביות, כפי שמוצג בסרטון, השתנתה מאז מרץ 2019? | M2: עד כמה השתנו תחושותיך כלפי הסרטון "סיפור על בלונים" מאז מרץ 2019?
A3: 40 | B3: 54 | C3: 2 | D3: 77 | E3: 0 | F3: 13 | G3: 69 | H3: 1 | I3: 99 | J3: 0 | K3: 64 | L3: 65 | M3: 60
A4: 19 | B4: 30 | C4: 85 | D4: 91 | E4: 5 | F4: 23 | G4: 20 | H4: 0 | I4: 99 | J4: 3 | K4: 89 | L4: 75 | M4: 85
A5: 65 | B5: 55 | C5: 61 | D5: 66 | E5: 38 | F5: 58 | G5: 33 | H5: 48 | I5: 100 | J5: 35 | K5: 80 | L5: 0 | M5: 0
A6: 30 | B6: 64 | C6: 0 | D6: 20 | E6: 50 | F6: 0 | G6: 66 | H6: 0 | I6: 38 | J6: 21 | K6: 53 | L6: 32 | M6: 23
A7: 2 | B7: 25 | C7: 2 | D7: 88 | E7: 1 | F7: 8 | G7: 11 | H7: 17 | I7: 87 | J7: 1 | K7: 3 | L7: 7 | M7: 0
A8: 41 | B8: 33 | C8: 57 | D8: 100 | E8: 12 | F8: 57 | G8: 47 | H8: 0 | I8: 92 | J8: 37 | K8: 98 | L8: 99 | M8: 0
A9: 24 | B9: 70 | C9: 14 | D9: 83 | E9: 22 | F9: 0 | G9: 28 | H9: 32 | I9: 89 | J9: 0 | K9: 68 | L9: 65 | M9: 76
A10: 0 | B10: 0 | C10: 0 | D10: 77 | E10: 0 | F10: 0 | G10: 0 | H10: 0 | I10: 100 | J10: 0 | K10: 0 | L10: 100 | M10: 0
A11: 21 | B11: 18 | C11: 17 | D11: 90 | E11: 12 | F11: 23 | G11: 0 | H11: 17 | I11: 93 | J11: 0 | K11: 79 | L11: 81 | M11: 11
A12: 0 | B12: 0 | C12: 0 | D12: 100 | E12: 4 | F12: 0 | G12: 0 | I12: 100 | J12: 10 | K12: 52 | L12: 100 | M12: 7
A13: 77 | B13: 87 | C13: 100 | D13: 0 | E13: 77 | F13: 70 | G13: 77 | H13: 100 | I13: 0 | J13: 1 | K13: 52 | L13: 3 | M13: 0
A14: 70 | B14: 87 | C14: 55 | D14: 58 | E14: 15 | F14: 13 | G14: 36 | H14: 73 | I14: 33 | J14: 9 | K14: 78 | L14: 82 | M14: 28
A15: 0 | B15: 31 | C15: 0 | D15: 81 | E15: 15 | F15: 0 | G15: 0 | H15: 0 | I15: 97 | J15: 0 | K15: 78 | L15: 16 | M15: 0
A16: 62 | B16: 63 | C16: 86 | D16: 63 | E16: 85 | F16: 26 | G16: 56 | H16: 92 | I16: 25 | J16: 54 | K16: 22 | L16: 10 | M16: 18
A17: 0 | B17: 13 | C17: 43 | D17: 97 | E17: 8 | F17: 0 | G17: 11 | I17: 71 | J17: 20 | K17: 0 | L17: 72 | M17: 20
A18: 63 | B18: 39 | C18: 61 | D18: 72 | E18: 28 | F18: 65 | G18: 38 | I18: 53 | J18: 61 | K18: 74 | L18: 51 | M18: 40
A19: 59 | B19: 100 | C19: 36 | D19: 23 | E19: 35 | F19: 4 | G19: 46 | H19: 0 | I19: 0 | J19: 3 | K19: 82 | L19: 79 | M19: 61
A20: 69 | B20: 70 | C20: 60 | D20: 76 | E20: 17 | F20: 26 | G20: 51 | H20: 24 | I20: 78 | J20: 18 | K20: 50 | L20: 71 | M20: 70
A21: 89 | B21: 92 | C21: 87 | D21: 23 | E21: 90 | F21: 67 | G21: 81 | H21: 84 | I21: 48 | J21: 78 | K21: 31 | L21: 0 | M21: 22
A22: 78 | B22: 26 | C22: 90 | D22: 65 | E22: 99 | F22: 56 | G22: 89 | H22: 87 | I22: 70 | J22: 95 | K22: 46 | L22: 0 | M22: 0
A23: 6 | B23: 84 | C23: 7 | D23: 91 | E23: 0 | F23: 7 | G23: 9 | I23: 100 | J23: 0 | K23: 21 | L23: 11 | M23: 0
J26: t-values | K26: =(AVERAGE(K3:K23)/(STDEV(K3:K23)/SQRT(COUNT(K3:K23)))) -> 8.0911044 | L26: =(AVERAGE(L3:L23)/(STDEV(L3:L23)/SQRT(COUNT(L3:L23)))) -> 5.9070429 | M26: =(AVERAGE(M3:M23)/(STDEV(M3:M23)/SQRT(COUNT(M3:M23)))) -> 3.9478081
J27: p-values | K27: =TDIST(K26, (COUNT(K3:K23) - 1), 2) -> 9.7814398e-08 | L27: =TDIST(L26, (COUNT(L3:L23) - 1), 2) -> 8.8877509e-06 | M27: =TDIST(M26, (COUNT(M3:M23) - 1), 2) -> 0.00079481988

Sheet Likud Ideology
A1: 2019 Recurring | C1: 2021 Recurring | E1: 2021 Only Once
A2: עד כמה את/ה חושב/ת שהאמירה "המצב הביטחוני, הכלכלי והחברתי בישראל מעולם לא היו טובים יותר" נכונה? | B2: עד כמה לדעתך החקירות וכתב האישום מהווים חלק מעבודתה הלגיטימית של התקשורת ככלב השמירה של הדמוקרטיה ושל השמאל כאופוזיציה? | C2: עד כמה את/ה חושב/ת שהאמירה "המצב הביטחוני, הכלכלי והחברתי בישראל מעולם לא היו טובים יותר" נכונה? | D2: עד כמה לדעתך החקירות וכתב האישום מהווים חלק מעבודתה הלגיטימית של התקשורת ככלב השמירה של הדמוקרטיה ושל השמאל כאופוזיציה? | E2: עד כמה דעתך על החלק בסרטון בו נתניהו מדבר על כך שמצבה של ישראל מעולם לא היה טוב יותר, השתנתה מאז מרץ 2019? | F2: האם דעתך על הקמת ממשלה עם המפלגות הערביות, כפי שמוצג בסרטון, השתנתה מאז מרץ 2019?
A3: 54 | B3: 77 | C3: 69 | D3: 99 | E3: 64 | F3: 65 | H3: =AVERAGE(C3:F3) -> 74.25
A4: 30 | B4: 91 | C4: 20 | D4: 99 | E4: 89 | F4: 75 | H4: =AVERAGE(C4:F4) -> 70.75
A5: 55 | B5: 66 | C5: 33 | D5: 100 | E5: 80 | F5: 0 | H5: =AVERAGE(C5:F5) -> 53.25
A6: 64 | B6: 20 | C6: 66 | D6: 38 | E6: 53 | F6: 32 | H6: =AVERAGE(C6:F6) -> 47.25
A7: 25 | B7: 88 | C7: 11 | D7: 87 | E7: 3 | F7: 7 | H7: =AVERAGE(C7:F7) -> 27
A8: 33 | B8: 100 | C8: 47 | D8: 92 | E8: 98 | F8: 99 | H8: =AVERAGE(C8:F8) -> 84
A9: 70 | B9: 83 | C9: 28 | D9: 89 | E9: 68 | F9: 65 | H9: =AVERAGE(C9:F9) -> 62.5
A10: 0 | B10: 77 | C10: 0 | D10: 100 | E10: 0 | F10: 100 | H10: =AVERAGE(C10:F10) -> 50
A11: 18 | B11: 90 | C11: 0 | D11: 93 | E11: 79 | F11: 81 | H11: =AVERAGE(C11:F11) -> 63.25
A12: 0 | B12: 100 | C12: 0 | D12: 100 | E12: 52 | F12: 100 | H12: =AVERAGE(C12:F12) -> 63
A13: 87 | B13: 0 | C13: 77 | D13: 0 | E13: 52 | F13: 3 | H13: =AVERAGE(C13:F13) -> 33
A14: 87 | B14: 58 | C14: 36 | D14: 33 | E14: 78 | F14: 82 | H14: =AVERAGE(C14:F14) -> 57.25
... A23: 84 | B23: 91 | C23: 9 | D23: 100 | E23: 21 | F23: 11 | H23: =AVERAGE(C23:F23) -> 35.25
D26: t-values | E26: =(AVERAGE(E3:E23)/(STDEV(E3:E23)/SQRT(COUNT(E3:E23)))) -> 8.0911044 | F26: =(AVERAGE(F3:F23)/(STDEV(F3:F23)/SQRT(COUNT(F3:F23)))) -> 5.9070429
D27: p-values | E27: =TDIST(E26, (COUNT(E3:E23) - 1), 2) -> 9.7814398e-08 | F27: =TDIST(F26, (COUNT(F3:F23) - 1), 2) -> 8.8877509e-06

Sheet Likud Ingroup
A1: 2019 Recurring | D1: 2021 Recurring | G1: 2021 Only Once
A2: עד כמה לדעתך ביבי האחראי היחיד והישיר להצלחות האדירות של ישראל בעשור האחרון? | B2: עד כמה לדעתך החקירות וכתב האישום מהווים רדיפה פוליטית של השמאל והתקשרות השמאלנית בישראל? | C2: עד כמה את/ה מאמין/ה שבתום ההליכים המשפטיים תוכח חפותו המוחלטת של ביבי? | D2: עד כמה לדעתך ביבי האחראי היחיד והישיר להצלחות האדירות של ישראל בעשור האחרון? | E2: עד כמה לדעתך החקירות וכתב האישום מהווים רדיפה פוליטית של השמאל והתקשרות השמאלנית בישראל? | F2: עד כמה את/ה מאמין/ה שבתום ההליכים המשפטיים תוכח חפותו המוחלטת של ביבי? | G2: עד כמה השתנו תחושותיך כלפי הסרטון "סיפור על בלונים" מאז מרץ 2019?
A3: 40 | B3: 2 | C3: 0 | D3: 13 | E3: 1 | F3: 0 | G3: 60 | I3: =AVERAGE(D3:G3) -> 18.5
A4: 19 | B4: 85 | C4: 5 | D4: 23 | E4: 0 | F4: 3 | G4: 85 | I4: =AVERAGE(D4:G4) -> 27.75
A5: 65 | B5: 61 | C5: 38 | D5: 58 | E5: 48 | F5: 35 | G5: 0 | I5: =AVERAGE(D5:G5) -> 35.25
A6: 30 | B6: 0 | C6: 50 | D6: 0 | E6: 0 | F6: 21 | G6: 23 | I6: =AVERAGE(D6:G6) -> 11
A7: 2 | B7: 2 | C7: 1 | D7: 8 | E7: 17 | F7: 1 | G7: 0 | I7: =AVERAGE(D7:G7) -> 6.5
A8: 41 | B8: 57 | C8: 12 | D8: 57 | E8: 0 | F8: 37 | G8: 0 | I8: =AVERAGE(D8:G8) -> 23.5
A9: 24 | B9: 14 | C9: 22 | D9: 0 | E9: 32 | F9: 0 | G9: 76 | I9: =AVERAGE(D9:G9) -> 27
A10: 0 | B10: 0 | C10: 0 | D10: 0 | E10: 0 | F10: 0 | G10: 0 | I10: =AVERAGE(D10:G10) -> 0
A11: 21 | B11: 17 | C11: 12 | D11: 23 | E11: 17 | F11: 0 | G11: 11 | I11: =AVERAGE(D11:G11) -> 12.75
A12: 0 | B12: 0 | C12: 4 | D12: 0 | F12: 10 | G12: 7 | I12: =AVERAGE(D12:G12) -> 5.6666667
A13: 77 | B13: 100 | C13: 77 | D13: 70 | E13: 100 | F13: 1 | G13: 0 | I13: =AVERAGE(D13:G13) -> 42.75
A14: 70 | B14: 55 | C14: 15 | D14: 13 | E14: 73 | F14: 9 | G14: 28 | I14: =AVERAGE(D14:G14) -> 30.75
A15: 0 | B15: 0 | C15: 15 | D15: 0 | E15: 0 | F15: 0 | G15: 0 | I15: =AVERAGE(D15:G15) -> 0
A16: 62 | B16: 86 | C16: 85 | D16: 26 | E16: 92 | F16: 54 | G16: 18 | I16: =AVERAGE(D16:G16) -> 47.5
A17: 0 | B17: 43 | C17: 8 | D17: 0 | F17: 20 | G17: 20 | I17: =AVERAGE(D17:G17) -> 13.333333
A18: 63 | B18: 61 | C18: 28 | D18: 65 | F18: 61 | G18: 40 | I18: =AVERAGE(D18:G18) -> 55.333333
A19: 59 | B19: 36 | C19: 35 | D19: 4 | E19: 0 | F19: 3 | G19: 61 | I19: =AVERAGE(D19:G19) -> 17
A20: 69 | B20: 60 | C20: 17 | D20: 26 | E20: 24 | F20: 18 | G20: 70 | I20: =AVERAGE(D20:G20) -> 34.5
A21: 89 | B21: 87 | C21: 90 | D21: 67 | E21: 84 | F21: 78 | G21: 22 | I21: =AVERAGE(D21:G21) -> 62.75
A22: 78 | B22: 90 | C22: 99 | D22: 56 | E22: 87 | F22: 95 | G22: 0 | I22: =AVERAGE(D22:G22) -> 59.5
A23: 6 | B23: 7 | C23: 0 | D23: 7 | F23: 0 | G23: 0 | I23: =AVERAGE(D23:G23) -> 2.3333333
F26: t-values | G26: =(AVERAGE(G3:G23)/(STDEV(G3:G23)/SQRT(COUNT(G3:G23)))) -> 3.9478081
F27: p-values | G27: =TDIST(G26, (COUNT(G3:G23) - 1), 2) -> 0.00079481988

Sheet Meretz-Avoda General
A1: 2019 Recurring | M1: 2021 Recurring | Y1: 2021 Only Once
A2: האם לדעתך הצגת הציבור הימני כ"לא נורמלי" משקפת את השמאל המנותק מהעם? | B2: עד כמה הדמויות הבאות נתפסות בעיניך כאמינות? 0 = דמות לא אמינה בכלל, 100 = דמות מאוד אמינה - תמר זנדברג | C2: עד כמה תמר זנדברג מעורר בך כל אחת מהתחושות הבאות?0 = כלל לא, 100 = מאוד - גאווה | D2: עד כמה תמר זנדברג מעורר בך כל אחת מהתחושות הבאות?0 = כלל לא, 100 = מאוד - תקווה | E2: עד כמה תמר זנדברג מעורר בך כל אחת מהתחושות הבאות?0 = כלל לא, 100 = מאוד - אהבה | F2: עד כמה תמר זנדברג מעורר בך כל אחת מהתחושות הבאות?0 = כלל לא, 100 = מאוד - כעס | G2: עד כמה תמר זנדברג מעורר בך כל אחת מהתחושות הבאות?0 = כלל לא, 100 = מאוד - בוז | H2: עד כמה תמר זנדברג מעורר בך כל אחת מהתחושות הבאות?0 = כלל לא, 100 = מאוד - שנאה | I2: עד כמה תמר זנדברג מעורר בך כל אחת מהתחושות הבאות?0 = כלל לא, 100 = מאוד - חרדה | J2: עד כמה תמר זנדברג מעורר בך כל אחת מהתחושות הבאות?0 = כלל לא, 100 = מאוד - ייאוש | K2: עד כמה תמר זנדברג מעורר בך כל אחת מהתחושות הבאות?0 = כלל לא, 100 = מאוד - אדישות | L2: עד כמה תמר זנדברג מעורר בך כל אחת מהתחושות הבאות?0 = כלל לא, 100 = מאוד - גועל | M2: האם לדעתך הצגת הציבור הימני כ"לא נורמלי" משקפת את השמאל המנותק מהעם? | N2: עד כמה הדמויות הבאות נתפסות בעיניך כאמינות? 0 = דמות לא אמינה בכלל, 100 = דמות מאוד אמינה - תמר זנדברג | O2: עד כמה תמר זנדברג מעורר בך כל אחת מהתחושות הבאות?0 = כלל לא, 100 = מאוד - גאווה | P2: עד כמה תמר זנדברג מעורר בך כל אחת מהתחושות הבאות?0 = כלל לא, 100 = מאוד - תקווה | Q2: עד כמה תמר זנדברג מעורר בך כל אחת מהתחושות הבאות?0 = כלל לא, 100 = מאוד - אהבה | R2: עד כמה תמר זנדברג מעורר בך כל אחת מהתחושות הבאות?0 = כלל לא, 100 = מאוד - כעס | S2: עד כמה תמר זנדברג מעורר בך כל אחת מהתחושות הבאות?0 = כלל לא, 100 = מאוד - בוז | T2: עד כמה תמר זנדברג מעורר בך כל אחת מהתחושות הבאות?0 = כלל לא, 100 = מאוד - שנאה | U2: עד כמה תמר זנדברג מעורר בך כל אחת מהתחושות הבאות?0 = כלל לא, 100 = מאוד - חרדה | V2: עד כמה תמר זנדברג מעורר בך כל אחת מהתחושות הבאות?0 = כלל לא, 100 = מאוד - ייאוש | W2: עד כמה תמר זנדברג מעורר בך כל אחת מהתחושות הבאות?0 = כלל לא, 100 = מאוד - אדישות | X2: עד כמה תמר זנדברג מעורר בך כל אחת מהתחושות הבאות?0 = כלל לא, 100 = מאוד - גועל | Y2: עד כמה הדעות שלך על תמר זנדברג השתנו מאז מרץ 2019? | Z2: עד כמה דעתך כלפי הסרטונים של מפלגת מרצ השתנתה מאז צפית בהם לראשונה במרץ 2019? | AA2: באיזו מידה דעותיך כלפי מירב מיכאלי השתנו מאז מרץ 2019? | AB2: כאשר צפית בסרטון של מפלגת העבודה, בחלק בו מופיעה סתיו שפיר, עד כמה תחושותיך השתנו מאז מרץ 2019? | AC2: כאשר צפית בסרטון של מפלגת העבודה, בחלק בו מופיע עמיר פרץ, עד כמה תחושותיך השתנו מאז מרץ 2019? | AD2: עד כמה הדעות שלך על אבי גבאי השתנו מאז שהוא פרש ממפלגת העבודה? | AE2: עד כמה דעתך כלפי מפלגת העבודה השתנתה מאז מרץ 2019? | AF2: עד כמה דעתך כלפי הסרטון של מפלגת העבודה השתנתה מאז צפית בהם לראשונה במרץ 2019?
A3: 27 | B3: 71 | C3: 20 | D3: 40 | E3: 0 | F3: 0 | G3: 0 | H3: 0 | I3: 0 | J3: 0 | K3: 0 | L3: 0 | M3: 1 | N3: 75 | O3: 30 | P3: 40 | Q3: 0 | R3: 10 | S3: 0 | T3: 0 | U3: 0 | V3: 0 | W3: 0 | X3: 1 | Y3: 64 | Z3: 1 | AA3: 100 | AB3: 60 | AC3: 77 | AD3: 54 | AE3: 87 | AF3: 2
A4: 14 | B4: 100 | C4: 90 | D4: 100 | E4: 90 | F4: 0 | G4: 0 | H4: 0 | I4: 0 | J4: 0 | K4: 0 | L4: 0 | M4: 17 | N4: 80 | O4: 90 | P4: 100 | Q4: 80 | R4: 0 | S4: 0 | T4: 0 | U4: 0 | V4: 0 | W4: 0 | X4: 0 | Y4: 6 | Z4: 14 | AA4: 26 | AB4: 0 | AC4: 0 | AD4: 96 | AE4: 22 | AF4: 75
A5: 92 | B5: 60 | C5: 0 | D5: 0 | E5: 0 | F5: 66 | G5: 66 | H5: 80 | I5: 0 | J5: 90 | K5: 38 | L5: 0 | M5: 82 | N5: 60 | O5: 6 | P5: 8 | Q5: 7 | R5: 66 | S5: 56 | T5: 57 | U5: 3 | V5: 85 | W5: 3 | X5: 32 | Y5: 37 | Z5: 0 | AA5: 100 | AB5: 0 | AC5: 68 | AD5: 0 | AE5: 100 | AF5: 0
A6: 57 | B6: 91 | C6: 64 | D6: 69 | E6: 74 | F6: 18 | G6: 4 | H6: 2 | I6: 17 | J6: 22 | K6: 2 | L6: 4 | M6: 77 | N6: 60 | O6: 41 | P6: 39 | Q6: 46 | R6: 32 | S6: 5 | T6: 6 | U6: 25 | V6: 2 | W6: 4 | X6: 3 | Y6: 65 | Z6: 66 | AA6: 74 | AB6: 35 | AC6: 35 | AD6: 33 | AE6: 64 | AF6: 61
A7: 13 | B7: 100 | C7: 91 | D7: 100 | E7: 90 | F7: 0 | G7: 0 | H7: 0 | I7: 0 | J7: 0 | K7: 0 | L7: 0 | M7: 24 | N7: 100 | O7: 18 | P7: 28 | Q7: 3 | R7: 0 | S7: 0 | T7: 0 | U7: 0 | V7: 0 | W7: 0 | X7: 0 | Y7: 8 | Z7: 55 | AA7: 55 | AB7: 66 | AC7: 67 | AD7: 48 | AE7: 50 | AF7: 58
